Workbook

Sheet Pick Module #1
U1: 1ST FLOOR | AO1: PICK MOD 1 | BP1: 1ST FLOOR
C4: TOTE FARM - 8' BAY | G4: TOTE FARM - 8' BAY | K4: M11-1-6C06 | L4: M11-1-6C05 | M4: M11-1-6C04 | N4: M11-1-6C03 | O4: M11-1-6C02 | P4: M11-1-6C01 | Q4: M11-1-5C06 | R4: M11-1-5C05 | S4: M11-1-5C04 | T4: M11-1-5C03 | U4: COLUMN | V4: M11-1-5C01 | W4: M11-1-4C06 | X4: M11-1-4C05 | Y4: M11-1-4C04 | Z4: M11-1-4C03 | AA4: M11-1-4C02 | AB4: M11-1-4C01 | AC4: M11-1-3C06 | AD4: M11-1-3C05 | AE4: M11-1-3C04 | AF4: M11-1-3C03 | AG4: M11-1-3C02 | AH4: M11-1-3C01 | AI4: M11-1-2C06 | AJ4: M11-1-2C05 | AK4: M11-1-2C04 | AL4: M11-1-2C03 | AM4: M11-1-2C02 | AN4: M11-1-2C01 | AO4: M11-1-1C06 | AP4: M11-1-1C05 | AQ4: M11-1-1C04 | AR4: M11-1-1C03 | AS4: M11-1-1C02 | AT4: M11-1-1C01 | AU4: M13-1-9C06 | AV4: M13-1-9C05 | AW4: M13-1-9C04 | AX4: M13-1-9C03 | AY4: M13-1-9C02 | AZ4: M13-1-9C01 | BA4: M13-1-8A01 | BB4: =IFERROR(VLOOKUP(BA4,'Module Items'!$A$1:$B$2587,2,FALSE),"") -> 51244 | BC4: =IFERROR(VLOOKUP(BA4,'Monthly Line Picks'!$A$1:$D$2000,4,FALSE),"0") -> 3 | BD4: M13-1-8A10 | BE4: =IFERROR(VLOOKUP(BD4,'Module Items'!$A$1:$B$2587,2,FALSE),"") -> 110177 | BF4: =IFERROR(VLOOKUP(BD4,'Monthly Line Picks'!$A$1:$D$2000,4,FALSE),"0") -> 22 | BG4: M13-1-8B09 | BH4: =IFERROR(VLOOKUP(BG4,'Module Items'!$A$1:$B$2587,2,FALSE),"") -> 1650 | BI4: =IFERROR(VLOOKUP(BG4,'Monthly Line Picks'!$A$1:$D$2000,4,FALSE),"0") -> 0 | BJ4: M13-1-8C06 | BK4: =IFERROR(VLOOKUP(BJ4,'Module Items'!$A$1:$B$2587,2,FALSE),"") -> 115493 | BL4: =IFERROR(VLOOKUP(BJ4,'Monthly Line Picks'!$A$1:$D$2000,4,FALSE),"0") -> 4 | BM4: M13-1-8D03 | BN4: =IFERROR(VLOOKUP(BM4,'Module Items'!$A$1:$B$2587,2,FALSE),"") -> 160377 | BO4: =IFERROR(VLOOKUP(BM4,'Monthly Line Picks'!$A$1:$D$2000,4,FALSE),"0") -> 25 | BP4: M13-1-8E02 | BQ4: =IFERROR(VLOOKUP(BP4,'Module Items'!$A$1:$B$2587,2,FALSE),"") -> 342 | BR4: =IFERROR(VLOOKUP(BP4,'Monthly Line Picks'!$A$1:$D$2000,4,FALSE),"0") -> 1 | BS4: COLUMN W/ FIRE EXTINGUISHER | BV4: WALKWAY | BY4: M13-1-6C06 | BZ4: M13-1-6C05 | CA4: M13-1-6C04 | CB4: M13-1-6C03 | CC4: M13-1-6C02 | CD4: M13-1-6C01 | CE4: M13-1-5C06 | CF4: M13-1-5C05 | CG4: M13-1-5C04 | CH4: M13-1-5C03 | CI4: M13-1-5C02 | CJ4: M13-1-5C01 | CK4: M13-1-4C06 | CL4: M13-1-4C05 | CM4: M13-1-4C04 | CN4: M13-1-4C03 | CO4: M13-1-4C02 | CP4: M13-1-4C01 | CQ4: M13-1-3C06 | CR4: M13-1-3C05 | CS4: M13-1-3C04 | CT4: M13-1-3C03 | CU4: M13-1-3C02 | CV4: M13-1-3C01 | CW4: M13-1-2C06 | CX4: M13-1-2C05 | CY4: M13-1-2C04 | CZ4: M13-1-2C03 | DA4: M13-1-2C02 | DB4: M13-1-2C01 | DC4: M13-1-1A01 | DD4: =IFERROR(VLOOKUP(DC4,'Module Items'!$A$1:$B$2587,2,FALSE),"") -> 62617 | DE4: =IFERROR(VLOOKUP(DC4,'Monthly Line Picks'!$A$1:$D$2000,4,FALSE),"0") -> 1 | DF4: M13-1-1A10 | DG4: =IFERROR(VLOOKUP(DF4,'Module Items'!$A$1:$B$2587,2,FALSE),"") -> 87064 | DH4: =IFERROR(VLOOKUP(DF4,'Monthly Line Picks'!$A$1:$D$2000,4,FALSE),"0") -> 21 | DI4: M13-1-1D03 | DJ4: =IFERROR(VLOOKUP(DI4,'Module Items'!$A$1:$B$2587,2,FALSE),"") -> 95802 | DK4: =IFERROR(VLOOKUP(DI4,'Monthly Line Picks'!$A$1:$D$2000,4,FALSE),"0") -> 8 | DL4: M13-1-1B09 | DM4: =IFERROR(VLOOKUP(DL4,'Module Items'!$A$1:$B$2587,2,FALSE),"") -> 131492 | DN4: =IFERROR(VLOOKUP(DL4,'Monthly Line Picks'!$A$1:$D$2000,4,FALSE),"0") -> 0 | DO4: M13-1-1C06 | DP4: =IFERROR(VLOOKUP(DO4,'Module Items'!$A$1:$B$2587,2,FALSE),"") -> 136011 | DQ4: =IFERROR(VLOOKUP(DO4,'Monthly Line Picks'!$A$1:$D$2000,4,FALSE),"0") -> 22 | DR4: M13-1-1E02 | DS4: =IFERROR(VLOOKUP(DR4,'Module Items'!$A$1:$B$2587,2,FALSE),"") -> 112644 | DT4: =IFERROR(VLOOKUP(DR4,'Monthly Line Picks'!$A$1:$D$2000,4,FALSE),"0") -> 0
K5: =IFERROR(VLOOKUP(K4,'Module Items'!$A$1:$B$2587,2,FALSE),"") -> 90495 | L5: =IFERROR(VLOOKUP(L4,'Module Items'!$A$1:$B$2587,2,FALSE),"") -> 60044 | M5: =IFERROR(VLOOKUP(M4,'Module Items'!$A$1:$B$2587,2,FALSE),"") -> 176124 | N5: =IFERROR(VLOOKUP(N4,'Module Items'!$A$1:$B$2587,2,FALSE),"") -> 133420 | O5: =IFERROR(VLOOKUP(O4,'Module Items'!$A$1:$B$2587,2,FALSE),"") -> 156308 | P5: =IFERROR(VLOOKUP(P4,'Module Items'!$A$1:$B$2587,2,FALSE),"") -> 138661 | Q5: =IFERROR(VLOOKUP(Q4,'Module Items'!$A$1:$B$2587,2,FALSE),"") -> 158198 | R5: =IFERROR(VLOOKUP(R4,'Module Items'!$A$1:$B$2587,2,FALSE),"") -> 131496 | ... T5: =IFERROR(VLOOKUP(T4,'Module Items'!$A$1:$B$2587,2,FALSE),"") -> 132831 | V5: =IFERROR(VLOOKUP(V4,'Module Items'!$A$1:$B$2587,2,FALSE),"") -> 159069 | W5: =IFERROR(VLOOKUP(W4,'Module Items'!$A$1:$B$2587,2,FALSE),"") -> 87480 | X5: =IFERROR(VLOOKUP(X4,'Module Items'!$A$1:$B$2587,2,FALSE),"") -> 93333 | Y5: =IFERROR(VLOOKUP(Y4,'Module Items'!$A$1:$B$2587,2,FALSE),"") -> 177110 | Z5: =IFERROR(VLOOKUP(Z4,'Module Items'!$A$1:$B$2587,2,FALSE),"") -> 97694 | AA5: =IFERROR(VLOOKUP(AA4,'Module Items'!$A$1:$B$2587,2,FALSE),"") -> 80793 | AB5: =IFERROR(VLOOKUP(AB4,'Module Items'!$A$1:$B$2587,2,FALSE),"") -> 95389 | AC5: =IFERROR(VLOOKUP(AC4,'Module Items'!$A$1:$B$2587,2,FALSE),"") -> 7494 | ... AZ5: =IFERROR(VLOOKUP(AZ4,'Module Items'!$A$1:$B$2587,2,FALSE),"") -> 119209 | BA5: M13-1-8A02 | BB5: =IFERROR(VLOOKUP(BA5,'Module Items'!$A$1:$B$2587,2,FALSE),"") -> 54537 | BC5: =IFERROR(VLOOKUP(BA5,'Monthly Line Picks'!$A$1:$D$2000,4,FALSE),"0") -> 0 | BD5: M13-1-8B01 | BE5: =IFERROR(VLOOKUP(BD5,'Module Items'!$A$1:$B$2587,2,FALSE),"") -> 111475 | BF5: =IFERROR(VLOOKUP(BD5,'Monthly Line Picks'!$A$1:$D$2000,4,FALSE),"0") -> 14 | BG5: M13-1-8B10 | BH5: =IFERROR(VLOOKUP(BG5,'Module Items'!$A$1:$B$2587,2,FALSE),"") -> 129566 | BI5: =IFERROR(VLOOKUP(BG5,'Monthly Line Picks'!$A$1:$D$2000,4,FALSE),"0") -> 8 | BJ5: M13-1-8C07 | BK5: =IFERROR(VLOOKUP(BJ5,'Module Items'!$A$1:$B$2587,2,FALSE),"") -> 112579 | BL5: =IFERROR(VLOOKUP(BJ5,'Monthly Line Picks'!$A$1:$D$2000,4,FALSE),"0") -> 0 | BM5: M13-1-8D04 | BN5: =IFERROR(VLOOKUP(BM5,'Module Items'!$A$1:$B$2587,2,FALSE),"") -> 83976 | BO5: =IFERROR(VLOOKUP(BM5,'Monthly Line Picks'!$A$1:$D$2000,4,FALSE),"0") -> 0 | BP5: M13-1-8E03 | BQ5: =IFERROR(VLOOKUP(BP5,'Module Items'!$A$1:$B$2587,2,FALSE),"") -> 141121 | BR5: =IFERROR(VLOOKUP(BP5,'Monthly Line Picks'!$A$1:$D$2000,4,FALSE),"0") -> 5 | BY5: =IFERROR(VLOOKUP(BY4,'Module Items'!$A$1:$B$2587,2,FALSE),"") -> 35067 | BZ5: =IFERROR(VLOOKUP(BZ4,'Module Items'!$A$1:$B$2587,2,FALSE),"") -> 142584 | CA5: =IFERROR(VLOOKUP(CA4,'Module Items'!$A$1:$B$2587,2,FALSE),"") -> 142821 | CB5: =IFERROR(VLOOKUP(CB4,'Module Items'!$A$1:$B$2587,2,FALSE),"") -> 9564 | CC5: =IFERROR(VLOOKUP(CC4,'Module Items'!$A$1:$B$2587,2,FALSE),"") -> 49660 | CD5: =IFERROR(VLOOKUP(CD4,'Module Items'!$A$1:$B$2587,2,FALSE),"") -> 113488 | CE5: =IFERROR(VLOOKUP(CE4,'Module Items'!$A$1:$B$2587,2,FALSE),"") -> 37831 | CF5: =IFERROR(VLOOKUP(CF4,'Module Items'!$A$1:$B$2587,2,FALSE),"") | ... DB5: =IFERROR(VLOOKUP(DB4,'Module Items'!$A$1:$B$2587,2,FALSE),"") -> 14454 | DC5: M13-1-1A02 | DD5: =IFERROR(VLOOKUP(DC5,'Module Items'!$A$1:$B$2587,2,FALSE),"") -> 30143 | DE5: =IFERROR(VLOOKUP(DC5,'Monthly Line Picks'!$A$1:$D$2000,4,FALSE),"0") -> 0 | DF5: M13-1-1B01 | DG5: =IFERROR(VLOOKUP(DF5,'Module Items'!$A$1:$B$2587,2,FALSE),"") -> 28740 | DH5: =IFERROR(VLOOKUP(DF5,'Monthly Line Picks'!$A$1:$D$2000,4,FALSE),"0") -> 14 | DI5: M13-1-1D04 | DJ5: =IFERROR(VLOOKUP(DI5,'Module Items'!$A$1:$B$2587,2,FALSE),"") -> 123377 | DK5: =IFERROR(VLOOKUP(DI5,'Monthly Line Picks'!$A$1:$D$2000,4,FALSE),"0") -> 0 | DL5: M13-1-1B10 | DM5: =IFERROR(VLOOKUP(DL5,'Module Items'!$A$1:$B$2587,2,FALSE),"") -> 13801 | DN5: =IFERROR(VLOOKUP(DL5,'Monthly Line Picks'!$A$1:$D$2000,4,FALSE),"0") -> 2 | DO5: M13-1-1C07 | DP5: =IFERROR(VLOOKUP(DO5,'Module Items'!$A$1:$B$2587,2,FALSE),"") -> 59405 | DQ5: =IFERROR(VLOOKUP(DO5,'Monthly Line Picks'!$A$1:$D$2000,4,FALSE),"0") -> 14 | DR5: M13-1-1E03 | DS5: =IFERROR(VLOOKUP(DR5,'Module Items'!$A$1:$B$2587,2,FALSE),"") -> 63938 | DT5: =IFERROR(VLOOKUP(DR5,'Monthly Line Picks'!$A$1:$D$2000,4,FALSE),"0") -> 14
K6: =IFERROR(VLOOKUP(K4,'Monthly Line Picks'!$A$1:$D$2101,4,FALSE),"0") -> 8 | L6: =IFERROR(VLOOKUP(L4,'Monthly Line Picks'!$A$1:$D$2101,4,FALSE),"0") -> 10 | M6: =IFERROR(VLOOKUP(M4,'Monthly Line Picks'!$A$1:$D$2101,4,FALSE),"0") -> 80 | N6: =IFERROR(VLOOKUP(N4,'Monthly Line Picks'!$A$1:$D$2101,4,FALSE),"0") -> 5 | O6: =IFERROR(VLOOKUP(O4,'Monthly Line Picks'!$A$1:$D$2101,4,FALSE),"0") -> 15 | P6: =IFERROR(VLOOKUP(P4,'Monthly Line Picks'!$A$1:$D$2101,4,FALSE),"0") -> 22 | Q6: =IFERROR(VLOOKUP(Q4,'Monthly Line Picks'!$A$1:$D$2101,4,FALSE),"0") -> 19 | R6: =IFERROR(VLOOKUP(R4,'Monthly Line Picks'!$A$1:$D$2101,4,FALSE),"0") -> 16 | ... T6: =IFERROR(VLOOKUP(T4,'Monthly Line Picks'!$A$1:$D$2101,4,FALSE),"0") -> 14 | V6: =IFERROR(VLOOKUP(V4,'Monthly Line Picks'!$A$1:$D$2101,4,FALSE),"0") -> 1 | W6: =IFERROR(VLOOKUP(W4,'Monthly Line Picks'!$A$1:$D$2101,4,FALSE),"0") -> 4 | X6: =IFERROR(VLOOKUP(X4,'Monthly Line Picks'!$A$1:$D$2101,4,FALSE),"0") -> 52 | Y6: =IFERROR(VLOOKUP(Y4,'Monthly Line Picks'!$A$1:$D$2101,4,FALSE),"0") -> 0 | Z6: =IFERROR(VLOOKUP(Z4,'Monthly Line Picks'!$A$1:$D$2101,4,FALSE),"0") -> 0 | AA6: =IFERROR(VLOOKUP(AA4,'Monthly Line Picks'!$A$1:$D$2101,4,FALSE),"0") -> 8 | AB6: =IFERROR(VLOOKUP(AB4,'Monthly Line Picks'!$A$1:$D$2101,4,FALSE),"0") -> 2 | AC6: =IFERROR(VLOOKUP(AC4,'Monthly Line Picks'!$A$1:$D$2101,4,FALSE),"0") -> 17 | ... AZ6: =IFERROR(VLOOKUP(AZ4,'Monthly Line Picks'!$A$1:$D$2101,4,FALSE),"0") -> 7 | BA6: M13-1-8A03 | BB6: =IFERROR(VLOOKUP(BA6,'Module Items'!$A$1:$B$2587,2,FALSE),"") -> 114868 | BC6: =IFERROR(VLOOKUP(BA6,'Monthly Line Picks'!$A$1:$D$2000,4,FALSE),"0") -> 27 | BD6: M13-1-8B02 | BE6: =IFERROR(VLOOKUP(BD6,'Module Items'!$A$1:$B$2587,2,FALSE),"") -> 96352 | BF6: =IFERROR(VLOOKUP(BD6,'Monthly Line Picks'!$A$1:$D$2000,4,FALSE),"0") -> 15 | BG6: M13-1-8C01 | BH6: =IFERROR(VLOOKUP(BG6,'Module Items'!$A$1:$B$2587,2,FALSE),"") -> OPEN | BI6: =IFERROR(VLOOKUP(BG6,'Monthly Line Picks'!$A$1:$D$2000,4,FALSE),"0") -> 0 | BJ6: M13-1-8C08 | BK6: =IFERROR(VLOOKUP(BJ6,'Module Items'!$A$1:$B$2587,2,FALSE),"") -> 67025 | BL6: =IFERROR(VLOOKUP(BJ6,'Monthly Line Picks'!$A$1:$D$2000,4,FALSE),"0") -> 1 | BM6: M13-1-8D05 | BN6: =IFERROR(VLOOKUP(BM6,'Module Items'!$A$1:$B$2587,2,FALSE),"") -> 141076 | BO6: =IFERROR(VLOOKUP(BM6,'Monthly Line Picks'!$A$1:$D$2000,4,FALSE),"0") -> 0 | BP6: M13-1-8E04 | BQ6: =IFERROR(VLOOKUP(BP6,'Module Items'!$A$1:$B$2587,2,FALSE),"") -> 72373 | BR6: =IFERROR(VLOOKUP(BP6,'Monthly Line Picks'!$A$1:$D$2000,4,FALSE),"0") -> 1 | BY6: =IFERROR(VLOOKUP(BY4,'Monthly Line Picks'!$A$1:$D$1458,4,FALSE),"0") -> 0 | BZ6: =IFERROR(VLOOKUP(BZ4,'Monthly Line Picks'!$A$1:$D$1458,4,FALSE),"0") -> 6 | CA6: =IFERROR(VLOOKUP(CA4,'Monthly Line Picks'!$A$1:$D$1458,4,FALSE),"0") -> 25 | CB6: =IFERROR(VLOOKUP(CB4,'Monthly Line Picks'!$A$1:$D$1458,4,FALSE),"0") -> 3 | CC6: =IFERROR(VLOOKUP(CC4,'Monthly Line Picks'!$A$1:$D$1458,4,FALSE),"0") -> 19 | CD6: =IFERROR(VLOOKUP(CD4,'Monthly Line Picks'!$A$1:$D$1458,4,FALSE),"0") -> 11 | CE6: =IFERROR(VLOOKUP(CE4,'Monthly Line Picks'!$A$1:$D$1458,4,FALSE),"0") -> 10 | CF6: =IFERROR(VLOOKUP(CF4,'Monthly Line Picks'!$A$1:$D$1458,4,FALSE),"0") -> 6 | ... DB6: =IFERROR(VLOOKUP(DB4,'Monthly Line Picks'!$A$1:$D$1458,4,FALSE),"0") -> 192 | DC6: M13-1-1A03 | DD6: =IFERROR(VLOOKUP(DC6,'Module Items'!$A$1:$B$2587,2,FALSE),"") -> 123945 | DE6: =IFERROR(VLOOKUP(DC6,'Monthly Line Picks'!$A$1:$D$2000,4,FALSE),"0") -> 5 | DF6: M13-1-1B02 | DG6: =IFERROR(VLOOKUP(DF6,'Module Items'!$A$1:$B$2587,2,FALSE),"") -> 81 | DH6: =IFERROR(VLOOKUP(DF6,'Monthly Line Picks'!$A$1:$D$2000,4,FALSE),"0") -> 4 | DI6: M13-1-1D05 | DJ6: =IFERROR(VLOOKUP(DI6,'Module Items'!$A$1:$B$2587,2,FALSE),"") -> 35196 | DK6: =IFERROR(VLOOKUP(DI6,'Monthly Line Picks'!$A$1:$D$2000,4,FALSE),"0") -> 10 | DL6: M13-1-1C01 | DM6: =IFERROR(VLOOKUP(DL6,'Module Items'!$A$1:$B$2587,2,FALSE),"") -> 330 | DN6: =IFERROR(VLOOKUP(DL6,'Monthly Line Picks'!$A$1:$D$2000,4,FALSE),"0") -> 1 | DO6: M13-1-1C08 | DP6: =IFERROR(VLOOKUP(DO6,'Module Items'!$A$1:$B$2587,2,FALSE),"") -> 173314 | DQ6: =IFERROR(VLOOKUP(DO6,'Monthly Line Picks'!$A$1:$D$2000,4,FALSE),"0") -> 0 | DR6: M13-1-1E04 | DS6: =IFERROR(VLOOKUP(DR6,'Module Items'!$A$1:$B$2587,2,FALSE),"") -> 8566 | DT6: =IFERROR(VLOOKUP(DR6,'Monthly Line Picks'!$A$1:$D$2000,4,FALSE),"0") -> 0
K7: M11-1-6B06 | L7: M11-1-6B05 | M7: M11-1-6B04 | N7: M11-1-6B03 | O7: M11-1-6B02 | P7: M11-1-6B01 | Q7: M11-1-5B06 | R7: M11-1-5B05 | S7: M11-1-5B04 | T7: M11-1-5B03 | V7: M11-1-5B01 | W7: M11-1-4B06 | X7: M11-1-4B05 | Y7: M11-1-4B04 | Z7: M11-1-4B03 | AA7: M11-1-4B02 | AB7: M11-1-4B01 | AC7: M11-1-3B06 | AD7: M11-1-3B05 | AE7: M11-1-3B04 | AF7: M11-1-3B03 | AG7: M11-1-3B02 | AH7: M11-1-3B01 | AI7: M11-1-2B06 | AJ7: M11-1-2B05 | AK7: M11-1-2B04 | AL7: M11-1-2B03 | AM7: M11-1-2B02 | AN7: M11-1-2B01 | AO7: M11-1-1B06 | AP7: M11-1-1B05 | AQ7: M11-1-1B04 | AR7: M11-1-1B03 | AS7: M11-1-1B02 | AT7: M11-1-1B01 | AU7: M13-1-9B06 | AV7: M13-1-9B05 | AW7: M13-1-9B04 | AX7: M13-1-9B03 | AY7: M13-1-9B02 | AZ7: M13-1-9B01 | BA7: M13-1-8A04 | BB7: =IFERROR(VLOOKUP(BA7,'Module Items'!$A$1:$B$2587,2,FALSE),"") -> 157511 | BC7: =IFERROR(VLOOKUP(BA7,'Monthly Line Picks'!$A$1:$D$2000,4,FALSE),"0") -> 10 | BD7: M13-1-8B03 | BE7: =IFERROR(VLOOKUP(BD7,'Module Items'!$A$1:$B$2587,2,FALSE),"") -> 159040 | BF7: =IFERROR(VLOOKUP(BD7,'Monthly Line Picks'!$A$1:$D$2000,4,FALSE),"0") -> 10 | BG7: M13-1-8C02 | BH7: =IFERROR(VLOOKUP(BG7,'Module Items'!$A$1:$B$2587,2,FALSE),"") -> 72374 | BI7: =IFERROR(VLOOKUP(BG7,'Monthly Line Picks'!$A$1:$D$2000,4,FALSE),"0") -> 0 | BJ7: M13-1-8C09 | BK7: =IFERROR(VLOOKUP(BJ7,'Module Items'!$A$1:$B$2587,2,FALSE),"") -> 1527 | BL7: =IFERROR(VLOOKUP(BJ7,'Monthly Line Picks'!$A$1:$D$2000,4,FALSE),"0") -> 0 | BM7: M13-1-8D06 | BN7: =IFERROR(VLOOKUP(BM7,'Module Items'!$A$1:$B$2587,2,FALSE),"") -> 107985 | BO7: =IFERROR(VLOOKUP(BM7,'Monthly Line Picks'!$A$1:$D$2000,4,FALSE),"0") -> 2 | BP7: M13-1-8E05 | BQ7: =IFERROR(VLOOKUP(BP7,'Module Items'!$A$1:$B$2587,2,FALSE),"") -> 172026 | BR7: =IFERROR(VLOOKUP(BP7,'Monthly Line Picks'!$A$1:$D$2000,4,FALSE),"0") -> 0 | BY7: M13-1-6B06 | BZ7: M13-1-6B05 | CA7: M13-1-6B04 | CB7: M13-1-6B03 | CC7: M13-1-6B02 | CD7: M13-1-6B01 | CE7: M13-1-5B06 | CF7: M13-1-5B05 | CG7: M13-1-5B04 | CH7: M13-1-5B03 | CI7: M13-1-5B02 | CJ7: M13-1-5B01 | CK7: M13-1-4B06 | CL7: M13-1-4B05 | CM7: M13-1-4B04 | CN7: M13-1-4B03 | CO7: M13-1-4B02 | CP7: M13-1-4B01 | CQ7: M13-1-3B06 | CR7: M13-1-3B05 | CS7: M13-1-3B04 | CT7: M13-1-3B03 | CU7: M13-1-3B02 | CV7: M13-1-3B01 | CW7: M13-1-2B06 | CX7: M13-1-2B05 | CY7: M13-1-2B04 | CZ7: M13-1-2B03 | DA7: M13-1-2B02 | DB7: M13-1-2B01 | DC7: M13-1-1A04 | DD7: =IFERROR(VLOOKUP(DC7,'Module Items'!$A$1:$B$2587,2,FALSE),"") -> 177087 | DE7: =IFERROR(VLOOKUP(DC7,'Monthly Line Picks'!$A$1:$D$2000,4,FALSE),"0") -> 12 | DF7: M13-1-1B03 | DG7: =IFERROR(VLOOKUP(DF7,'Module Items'!$A$1:$B$2587,2,FALSE),"") -> 8250 | DH7: =IFERROR(VLOOKUP(DF7,'Monthly Line Picks'!$A$1:$D$2000,4,FALSE),"0") -> 0 | DI7: M13-1-1D06 | DJ7: =IFERROR(VLOOKUP(DI7,'Module Items'!$A$1:$B$2587,2,FALSE),"") -> 177134 | DK7: =IFERROR(VLOOKUP(DI7,'Monthly Line Picks'!$A$1:$D$2000,4,FALSE),"0") -> 0 | DL7: M13-1-1C02 | DM7: =IFERROR(VLOOKUP(DL7,'Module Items'!$A$1:$B$2587,2,FALSE),"") -> 144144 | DN7: =IFERROR(VLOOKUP(DL7,'Monthly Line Picks'!$A$1:$D$2000,4,FALSE),"0") -> 12 | DO7: M13-1-1C09 | DP7: =IFERROR(VLOOKUP(DO7,'Module Items'!$A$1:$B$2587,2,FALSE),"") -> 115909 | DQ7: =IFERROR(VLOOKUP(DO7,'Monthly Line Picks'!$A$1:$D$2000,4,FALSE),"0") -> 0 | DR7: M13-1-1E05 | DS7: =IFERROR(VLOOKUP(DR7,'Module Items'!$A$1:$B$2587,2,FALSE),"") -> 156659 | DT7: =IFERROR(VLOOKUP(DR7,'Monthly Line Picks'!$A$1:$D$2000,4,FALSE),"0") -> 0
K8: =IFERROR(VLOOKUP(K7,'Module Items'!$A$1:$B$2587,2,FALSE),"") -> 661 | L8: =IFERROR(VLOOKUP(L7,'Module Items'!$A$1:$B$2587,2,FALSE),"") -> 142657 | M8: =IFERROR(VLOOKUP(M7,'Module Items'!$A$1:$B$2587,2,FALSE),"") -> 136330 | N8: =IFERROR(VLOOKUP(N7,'Module Items'!$A$1:$B$2587,2,FALSE),"") -> 77908 | O8: =IFERROR(VLOOKUP(O7,'Module Items'!$A$1:$B$2587,2,FALSE),"") -> 94840 | P8: =IFERROR(VLOOKUP(P7,'Module Items'!$A$1:$B$2587,2,FALSE),"") -> 114170 | Q8: =IFERROR(VLOOKUP(Q7,'Module Items'!$A$1:$B$2587,2,FALSE),"") -> 133639 | R8: =IFERROR(VLOOKUP(R7,'Module Items'!$A$1:$B$2587,2,FALSE),"") -> 134290 | ... T8: =IFERROR(VLOOKUP(T7,'Module Items'!$A$1:$B$2587,2,FALSE),"") -> 138510 | V8: =IFERROR(VLOOKUP(V7,'Module Items'!$A$1:$B$2587,2,FALSE),"") -> 159074 | W8: =IFERROR(VLOOKUP(W7,'Module Items'!$A$1:$B$2587,2,FALSE),"") -> 104614 | X8: =IFERROR(VLOOKUP(X7,'Module Items'!$A$1:$B$2587,2,FALSE),"") -> 106380 | Y8: =IFERROR(VLOOKUP(Y7,'Module Items'!$A$1:$B$2587,2,FALSE),"") -> 108468 | Z8: =IFERROR(VLOOKUP(Z7,'Module Items'!$A$1:$B$2587,2,FALSE),"") -> 112169 | AA8: =IFERROR(VLOOKUP(AA7,'Module Items'!$A$1:$B$2587,2,FALSE),"") -> 157430 | AB8: =IFERROR(VLOOKUP(AB7,'Module Items'!$A$1:$B$2587,2,FALSE),"") -> 12778 | AC8: =IFERROR(VLOOKUP(AC7,'Module Items'!$A$1:$B$2587,2,FALSE),"") -> 20032 | ... AZ8: =IFERROR(VLOOKUP(AZ7,'Module Items'!$A$1:$B$2587,2,FALSE),"") -> 159072 | BA8: M13-1-8A05 | BB8: =IFERROR(VLOOKUP(BA8,'Module Items'!$A$1:$B$2587,2,FALSE),"") -> 1963 | BC8: =IFERROR(VLOOKUP(BA8,'Monthly Line Picks'!$A$1:$D$2000,4,FALSE),"0") -> 8 | BD8: M13-1-8B04 | BE8: =IFERROR(VLOOKUP(BD8,'Module Items'!$A$1:$B$2587,2,FALSE),"") -> 63509 | BF8: =IFERROR(VLOOKUP(BD8,'Monthly Line Picks'!$A$1:$D$2000,4,FALSE),"0") -> 1 | BG8: M13-1-8C03 | BH8: =IFERROR(VLOOKUP(BG8,'Module Items'!$A$1:$B$2587,2,FALSE),"") -> 157858 | BI8: =IFERROR(VLOOKUP(BG8,'Monthly Line Picks'!$A$1:$D$2000,4,FALSE),"0") -> 2 | BJ8: M13-1-8C10 | BK8: =IFERROR(VLOOKUP(BJ8,'Module Items'!$A$1:$B$2587,2,FALSE),"") -> 89977 | BL8: =IFERROR(VLOOKUP(BJ8,'Monthly Line Picks'!$A$1:$D$2000,4,FALSE),"0") -> 0 | BM8: M13-1-8D07 | BN8: =IFERROR(VLOOKUP(BM8,'Module Items'!$A$1:$B$2587,2,FALSE),"") -> 105911 | BO8: =IFERROR(VLOOKUP(BM8,'Monthly Line Picks'!$A$1:$D$2000,4,FALSE),"0") -> 2 | BP8: M13-1-8E06 | BQ8: =IFERROR(VLOOKUP(BP8,'Module Items'!$A$1:$B$2587,2,FALSE),"") -> 112585 | BR8: =IFERROR(VLOOKUP(BP8,'Monthly Line Picks'!$A$1:$D$2000,4,FALSE),"0") -> 0 | BY8: =IFERROR(VLOOKUP(BY7,'Module Items'!$A$1:$B$2587,2,FALSE),"") -> 37932 | BZ8: =IFERROR(VLOOKUP(BZ7,'Module Items'!$A$1:$B$2587,2,FALSE),"") -> 1814 | CA8: =IFERROR(VLOOKUP(CA7,'Module Items'!$A$1:$B$2587,2,FALSE),"") -> 59643 | CB8: =IFERROR(VLOOKUP(CB7,'Module Items'!$A$1:$B$2587,2,FALSE),"") -> 133699 | CC8: =IFERROR(VLOOKUP(CC7,'Module Items'!$A$1:$B$2587,2,FALSE),"") -> 27272 | CD8: =IFERROR(VLOOKUP(CD7,'Module Items'!$A$1:$B$2587,2,FALSE),"") -> 159194 | CE8: =IFERROR(VLOOKUP(CE7,'Module Items'!$A$1:$B$2587,2,FALSE),"") -> 108955 | CF8: =IFERROR(VLOOKUP(CF7,'Module Items'!$A$1:$B$2587,2,FALSE),"") -> 110812 | ... DB8: =IFERROR(VLOOKUP(DB7,'Module Items'!$A$1:$B$2587,2,FALSE),"") -> 100379 | DC8: M13-1-1A05 | DD8: =IFERROR(VLOOKUP(DC8,'Module Items'!$A$1:$B$2587,2,FALSE),"") -> 107130 | DE8: =IFERROR(VLOOKUP(DC8,'Monthly Line Picks'!$A$1:$D$2000,4,FALSE),"0") -> 29 | DF8: M13-1-1B04 | DG8: =IFERROR(VLOOKUP(DF8,'Module Items'!$A$1:$B$2587,2,FALSE),"") -> 192 | DH8: =IFERROR(VLOOKUP(DF8,'Monthly Line Picks'!$A$1:$D$2000,4,FALSE),"0") -> 7 | DI8: M13-1-1D07 | DJ8: =IFERROR(VLOOKUP(DI8,'Module Items'!$A$1:$B$2587,2,FALSE),"") -> 127138 | DK8: =IFERROR(VLOOKUP(DI8,'Monthly Line Picks'!$A$1:$D$2000,4,FALSE),"0") -> 17 | DL8: M13-1-1C03 | DM8: =IFERROR(VLOOKUP(DL8,'Module Items'!$A$1:$B$2587,2,FALSE),"") -> 100826 | DN8: =IFERROR(VLOOKUP(DL8,'Monthly Line Picks'!$A$1:$D$2000,4,FALSE),"0") -> 12 | DO8: M13-1-1C10 | DP8: =IFERROR(VLOOKUP(DO8,'Module Items'!$A$1:$B$2587,2,FALSE),"") -> 172419 | DQ8: =IFERROR(VLOOKUP(DO8,'Monthly Line Picks'!$A$1:$D$2000,4,FALSE),"0") -> 0 | DR8: M13-1-1E06 | DS8: =IFERROR(VLOOKUP(DR8,'Module Items'!$A$1:$B$2587,2,FALSE),"") -> 109160 | DT8: =IFERROR(VLOOKUP(DR8,'Monthly Line Picks'!$A$1:$D$2000,4,FALSE),"0") -> 0
K9: =IFERROR(VLOOKUP(K7,'Monthly Line Picks'!$A$1:$D$2101,4,FALSE),"0") -> 97 | L9: =IFERROR(VLOOKUP(L7,'Monthly Line Picks'!$A$1:$D$2101,4,FALSE),"0") -> 14 | M9: =IFERROR(VLOOKUP(M7,'Monthly Line Picks'!$A$1:$D$2101,4,FALSE),"0") -> 0 | N9: =IFERROR(VLOOKUP(N7,'Monthly Line Picks'!$A$1:$D$2101,4,FALSE),"0") -> 4 | O9: =IFERROR(VLOOKUP(O7,'Monthly Line Picks'!$A$1:$D$2101,4,FALSE),"0") -> 18 | P9: =IFERROR(VLOOKUP(P7,'Monthly Line Picks'!$A$1:$D$2101,4,FALSE),"0") -> 33 | Q9: =IFERROR(VLOOKUP(Q7,'Monthly Line Picks'!$A$1:$D$2101,4,FALSE),"0") -> 1 | R9: =IFERROR(VLOOKUP(R7,'Monthly Line Picks'!$A$1:$D$2101,4,FALSE),"0") -> 17 | ... T9: =IFERROR(VLOOKUP(T7,'Monthly Line Picks'!$A$1:$D$2101,4,FALSE),"0") -> 19 | V9: =IFERROR(VLOOKUP(V7,'Monthly Line Picks'!$A$1:$D$2101,4,FALSE),"0") -> 1 | W9: =IFERROR(VLOOKUP(W7,'Monthly Line Picks'!$A$1:$D$2101,4,FALSE),"0") -> 8 | X9: =IFERROR(VLOOKUP(X7,'Monthly Line Picks'!$A$1:$D$2101,4,FALSE),"0") -> 8 | Y9: =IFERROR(VLOOKUP(Y7,'Monthly Line Picks'!$A$1:$D$2101,4,FALSE),"0") -> 6 | Z9: =IFERROR(VLOOKUP(Z7,'Monthly Line Picks'!$A$1:$D$2101,4,FALSE),"0") -> 0 | AA9: =IFERROR(VLOOKUP(AA7,'Monthly Line Picks'!$A$1:$D$2101,4,FALSE),"0") -> 2 | AB9: =IFERROR(VLOOKUP(AB7,'Monthly Line Picks'!$A$1:$D$2101,4,FALSE),"0") -> 15 | AC9: =IFERROR(VLOOKUP(AC7,'Monthly Line Picks'!$A$1:$D$2101,4,FALSE),"0") -> 7 | ... AZ9: =IFERROR(VLOOKUP(AZ7,'Monthly Line Picks'!$A$1:$D$2101,4,FALSE),"0") -> 23 | BA9: M13-1-8A06 | BB9: =IFERROR(VLOOKUP(BA9,'Module Items'!$A$1:$B$2587,2,FALSE),"") -> 84734 | BC9: =IFERROR(VLOOKUP(BA9,'Monthly Line Picks'!$A$1:$D$2000,4,FALSE),"0") -> 6 | BD9: M13-1-8B05 | BE9: =IFERROR(VLOOKUP(BD9,'Module Items'!$A$1:$B$2587,2,FALSE),"") -> 94823 | BF9: =IFERROR(VLOOKUP(BD9,'Monthly Line Picks'!$A$1:$D$2000,4,FALSE),"0") -> 13 | BG9: M13-1-8C04 | BH9: =IFERROR(VLOOKUP(BG9,'Module Items'!$A$1:$B$2587,2,FALSE),"") -> 129515 | BI9: =IFERROR(VLOOKUP(BG9,'Monthly Line Picks'!$A$1:$D$2000,4,FALSE),"0") -> 18 | BJ9: M13-1-8D01 | BK9: =IFERROR(VLOOKUP(BJ9,'Module Items'!$A$1:$B$2587,2,FALSE),"") -> 160375 | BL9: =IFERROR(VLOOKUP(BJ9,'Monthly Line Picks'!$A$1:$D$2000,4,FALSE),"0") -> 15 | BM9: M13-1-8D08 | BN9: =IFERROR(VLOOKUP(BM9,'Module Items'!$A$1:$B$2587,2,FALSE),"") -> 100024 | BO9: =IFERROR(VLOOKUP(BM9,'Monthly Line Picks'!$A$1:$D$2000,4,FALSE),"0") -> 1 | BP9: M13-1-8E07 | BQ9: =IFERROR(VLOOKUP(BP9,'Module Items'!$A$1:$B$2587,2,FALSE),"") -> 71469 | BR9: =IFERROR(VLOOKUP(BP9,'Monthly Line Picks'!$A$1:$D$2000,4,FALSE),"0") -> 0 | BY9: =IFERROR(VLOOKUP(BY7,'Monthly Line Picks'!$A$1:$D$1458,4,FALSE),"0") -> 8 | BZ9: =IFERROR(VLOOKUP(BZ7,'Monthly Line Picks'!$A$1:$D$1458,4,FALSE),"0") -> 14 | CA9: =IFERROR(VLOOKUP(CA7,'Monthly Line Picks'!$A$1:$D$1458,4,FALSE),"0") -> 28 | CB9: =IFERROR(VLOOKUP(CB7,'Monthly Line Picks'!$A$1:$D$1458,4,FALSE),"0") -> 54 | CC9: =IFERROR(VLOOKUP(CC7,'Monthly Line Picks'!$A$1:$D$1458,4,FALSE),"0") -> 10 | CD9: =IFERROR(VLOOKUP(CD7,'Monthly Line Picks'!$A$1:$D$1458,4,FALSE),"0") -> 45 | CE9: =IFERROR(VLOOKUP(CE7,'Monthly Line Picks'!$A$1:$D$1458,4,FALSE),"0") -> 0 | CF9: =IFERROR(VLOOKUP(CF7,'Monthly Line Picks'!$A$1:$D$1458,4,FALSE),"0") -> 19 | ... DB9: =IFERROR(VLOOKUP(DB7,'Monthly Line Picks'!$A$1:$D$1458,4,FALSE),"0") -> 255 | DC9: M13-1-1A06 | DD9: =IFERROR(VLOOKUP(DC9,'Module Items'!$A$1:$B$2587,2,FALSE),"") -> 100134 | DE9: =IFERROR(VLOOKUP(DC9,'Monthly Line Picks'!$A$1:$D$2000,4,FALSE),"0") -> 1 | DF9: M13-1-1B05 | DG9: =IFERROR(VLOOKUP(DF9,'Module Items'!$A$1:$B$2587,2,FALSE),"") -> 116911 | DH9: =IFERROR(VLOOKUP(DF9,'Monthly Line Picks'!$A$1:$D$2000,4,FALSE),"0") -> 20 | DI9: M13-1-1D08 | DJ9: =IFERROR(VLOOKUP(DI9,'Module Items'!$A$1:$B$2587,2,FALSE),"") -> 59632 | DK9: =IFERROR(VLOOKUP(DI9,'Monthly Line Picks'!$A$1:$D$2000,4,FALSE),"0") -> 19 | DL9: M13-1-1C04 | DM9: =IFERROR(VLOOKUP(DL9,'Module Items'!$A$1:$B$2587,2,FALSE),"") -> 61323 | DN9: =IFERROR(VLOOKUP(DL9,'Monthly Line Picks'!$A$1:$D$2000,4,FALSE),"0") -> 0 | DO9: M13-1-1D01 | DP9: =IFERROR(VLOOKUP(DO9,'Module Items'!$A$1:$B$2587,2,FALSE),"") -> 18598 | DQ9: =IFERROR(VLOOKUP(DO9,'Monthly Line Picks'!$A$1:$D$2000,4,FALSE),"0") -> 2 | DR9: M13-1-1E07 | DS9: =IFERROR(VLOOKUP(DR9,'Module Items'!$A$1:$B$2587,2,FALSE),"") -> 65803 | DT9: =IFERROR(VLOOKUP(DR9,'Monthly Line Picks'!$A$1:$D$2000,4,FALSE),"0") -> 10
K10: M11-1-6A06 | L10: M11-1-6A05 | M10: M11-1-6A04 | N10: M11-1-6A03 | O10: M11-1-6A02 | P10: M11-1-6A01 | Q10: M11-1-5A06 | R10: M11-1-5A05 | S10: M11-1-5A04 | T10: M11-1-5A03 | V10: M11-1-5A01 | W10: M11-1-4A06 | X10: M11-1-4A05 | Y10: M11-1-4A04 | Z10: M11-1-4A03 | AA10: M11-1-4A02 | AB10: M11-1-4A01 | AC10: M11-1-3A06 | AD10: M11-1-3A05 | AE10: M11-1-3A04 | AF10: M11-1-3A03 | AG10: M11-1-3A02 | AH10: M11-1-3A01 | AI10: M11-1-2A06 | AJ10: M11-1-2A05 | AK10: M11-1-2A04 | AL10: M11-1-2A03 | AM10: M11-1-2A02 | AN10: M11-1-2A01 | AO10: M11-1-1A06 | AP10: M11-1-1A05 | AQ10: M11-1-1A04 | AR10: M11-1-1A03 | AS10: M11-1-1A02 | AT10: M11-1-1A01 | AU10: M13-1-9A06 | AV10: M13-1-9A05 | AW10: M13-1-9A04 | AX10: M13-1-9A03 | AY10: M13-1-9A02 | AZ10: M13-1-9A01 | BA10: M13-1-8A07 | BB10: =IFERROR(VLOOKUP(BA10,'Module Items'!$A$1:$B$2587,2,FALSE),"") -> 903 | BC10: =IFERROR(VLOOKUP(BA10,'Monthly Line Picks'!$A$1:$D$2000,4,FALSE),"0") -> 8 | BD10: M13-1-8B06 | BE10: =IFERROR(VLOOKUP(BD10,'Module Items'!$A$1:$B$2587,2,FALSE),"") -> 1470 | BF10: =IFERROR(VLOOKUP(BD10,'Monthly Line Picks'!$A$1:$D$2000,4,FALSE),"0") -> 0 | BG10: M13-1-8C05 | BH10: =IFERROR(VLOOKUP(BG10,'Module Items'!$A$1:$B$2587,2,FALSE),"") -> 61324 | BI10: =IFERROR(VLOOKUP(BG10,'Monthly Line Picks'!$A$1:$D$2000,4,FALSE),"0") -> 0 | BJ10: M13-1-8D02 | BK10: =IFERROR(VLOOKUP(BJ10,'Module Items'!$A$1:$B$2587,2,FALSE),"") -> 142571 | BL10: =IFERROR(VLOOKUP(BJ10,'Monthly Line Picks'!$A$1:$D$2000,4,FALSE),"0") -> 0 | BM10: M13-1-8D09 | BN10: =IFERROR(VLOOKUP(BM10,'Module Items'!$A$1:$B$2587,2,FALSE),"") -> 74609 | BO10: =IFERROR(VLOOKUP(BM10,'Monthly Line Picks'!$A$1:$D$2000,4,FALSE),"0") -> 2 | BP10: M13-1-8E08 | BQ10: =IFERROR(VLOOKUP(BP10,'Module Items'!$A$1:$B$2587,2,FALSE),"") -> 82792 | BR10: =IFERROR(VLOOKUP(BP10,'Monthly Line Picks'!$A$1:$D$2000,4,FALSE),"0") -> 3 | BY10: M13-1-6A06 | BZ10: M13-1-6A05 | CA10: M13-1-6A04 | CB10: M13-1-6A03 | CC10: M13-1-6A02 | CD10: M13-1-6A01 | CE10: M13-1-5A06 | CF10: M13-1-5A05 | CG10: M13-1-5A04 | CH10: M13-1-5A03 | CI10: M13-1-5A02 | CJ10: M13-1-5A01 | CK10: M13-1-4A06 | CL10: M13-1-4A05 | CM10: M13-1-4A04 | CN10: M13-1-4A03 | CO10: M13-1-4A02 | CP10: M13-1-4A01 | CQ10: M13-1-3A06 | CR10: M13-1-3A05 | CS10: M13-1-3A04 | CT10: M13-1-3A03 | CU10: M13-1-3A02 | CV10: M13-1-3A01 | CW10: M13-1-2A06 | CX10: M13-1-2A05 | CY10: M13-1-2A04 | CZ10: M13-1-2A03 | DA10: M13-1-2A02 | DB10: M13-1-2A01 | DC10: M13-1-1A07 | DD10: =IFERROR(VLOOKUP(DC10,'Module Items'!$A$1:$B$2587,2,FALSE),"") -> 65257 | DE10: =IFERROR(VLOOKUP(DC10,'Monthly Line Picks'!$A$1:$D$2000,4,FALSE),"0") -> 7 | DF10: M13-1-1B06 | DG10: =IFERROR(VLOOKUP(DF10,'Module Items'!$A$1:$B$2587,2,FALSE),"") -> 63153 | DH10: =IFERROR(VLOOKUP(DF10,'Monthly Line Picks'!$A$1:$D$2000,4,FALSE),"0") -> 23 | DI10: M13-1-1D09 | DJ10: =IFERROR(VLOOKUP(DI10,'Module Items'!$A$1:$B$2587,2,FALSE),"") | DK10: =IFERROR(VLOOKUP(DI10,'Monthly Line Picks'!$A$1:$D$2000,4,FALSE),"0") -> 0 | DL10: M13-1-1C05 | DM10: =IFERROR(VLOOKUP(DL10,'Module Items'!$A$1:$B$2587,2,FALSE),"") -> 157703 | DN10: =IFERROR(VLOOKUP(DL10,'Monthly Line Picks'!$A$1:$D$2000,4,FALSE),"0") -> 2 | DO10: M13-1-1D02 | DP10: =IFERROR(VLOOKUP(DO10,'Module Items'!$A$1:$B$2587,2,FALSE),"") -> 127265 | DQ10: =IFERROR(VLOOKUP(DO10,'Monthly Line Picks'!$A$1:$D$2000,4,FALSE),"0") -> 52 | DR10: M13-1-1E08 | DS10: =IFERROR(VLOOKUP(DR10,'Module Items'!$A$1:$B$2587,2,FALSE),"") -> 11552 | DT10: =IFERROR(VLOOKUP(DR10,'Monthly Line Picks'!$A$1:$D$2000,4,FALSE),"0") -> 8
K11: =IFERROR(VLOOKUP(K10,'Module Items'!$A$1:$B$2587,2,FALSE),"") -> 95995 | L11: =IFERROR(VLOOKUP(L10,'Module Items'!$A$1:$B$2587,2,FALSE),"") -> 1966 | M11: =IFERROR(VLOOKUP(M10,'Module Items'!$A$1:$B$2587,2,FALSE),"") -> 116845 | N11: =IFERROR(VLOOKUP(N10,'Module Items'!$A$1:$B$2587,2,FALSE),"") -> 88216 | O11: =IFERROR(VLOOKUP(O10,'Module Items'!$A$1:$B$2587,2,FALSE),"") -> 119975 | P11: =IFERROR(VLOOKUP(P10,'Module Items'!$A$1:$B$2587,2,FALSE),"") -> 84582 | Q11: =IFERROR(VLOOKUP(Q10,'Module Items'!$A$1:$B$2587,2,FALSE),"") -> 138946 | R11: =IFERROR(VLOOKUP(R10,'Module Items'!$A$1:$B$2587,2,FALSE),"") -> 139050 | ... T11: =IFERROR(VLOOKUP(T10,'Module Items'!$A$1:$B$2587,2,FALSE),"") -> 126103 | V11: =IFERROR(VLOOKUP(V10,'Module Items'!$A$1:$B$2587,2,FALSE),"") -> 116906 | W11: =IFERROR(VLOOKUP(W10,'Module Items'!$A$1:$B$2587,2,FALSE),"") | X11: =IFERROR(VLOOKUP(X10,'Module Items'!$A$1:$B$2587,2,FALSE),"") -> 97706 | Y11: =IFERROR(VLOOKUP(Y10,'Module Items'!$A$1:$B$2587,2,FALSE),"") -> 1030 | Z11: =IFERROR(VLOOKUP(Z10,'Module Items'!$A$1:$B$2587,2,FALSE),"") -> 118443 | AA11: =IFERROR(VLOOKUP(AA10,'Module Items'!$A$1:$B$2587,2,FALSE),"") -> 1461 | AB11: =IFERROR(VLOOKUP(AB10,'Module Items'!$A$1:$B$2587,2,FALSE),"") -> 124940 | AC11: =IFERROR(VLOOKUP(AC10,'Module Items'!$A$1:$B$2587,2,FALSE),"") -> 68068 | ... AZ11: =IFERROR(VLOOKUP(AZ10,'Module Items'!$A$1:$B$2587,2,FALSE),"") -> 102965 | BA11: M13-1-8A08 | BB11: =IFERROR(VLOOKUP(BA11,'Module Items'!$A$1:$B$2587,2,FALSE),"") -> 101391 | BC11: =IFERROR(VLOOKUP(BA11,'Monthly Line Picks'!$A$1:$D$2000,4,FALSE),"0") -> 13 | BD11: M13-1-8B07 | BE11: =IFERROR(VLOOKUP(BD11,'Module Items'!$A$1:$B$2587,2,FALSE),"") -> 173039 | BF11: =IFERROR(VLOOKUP(BD11,'Monthly Line Picks'!$A$1:$D$2000,4,FALSE),"0") -> 49 | BG11: WALK-IN SHELVES | BK11: =IFERROR(VLOOKUP(BJ11,'Module Items'!$A$1:$B$2587,2,FALSE),"") | BL11: =IFERROR(VLOOKUP(BJ11,'Monthly Line Picks'!$A$1:$D$2101,4,FALSE),"") | BM11: M13-1-8D10 | BN11: =IFERROR(VLOOKUP(BM11,'Module Items'!$A$1:$B$2587,2,FALSE),"") -> 83463 | BO11: =IFERROR(VLOOKUP(BM11,'Monthly Line Picks'!$A$1:$D$2000,4,FALSE),"0") -> 3 | BP11: M13-1-8E09 | BQ11: =IFERROR(VLOOKUP(BP11,'Module Items'!$A$1:$B$2587,2,FALSE),"") -> 2236 | BR11: =IFERROR(VLOOKUP(BP11,'Monthly Line Picks'!$A$1:$D$2000,4,FALSE),"0") -> 0 | BY11: =IFERROR(VLOOKUP(BY10,'Module Items'!$A$1:$B$2587,2,FALSE),"") -> 86760 | BZ11: =IFERROR(VLOOKUP(BZ10,'Module Items'!$A$1:$B$2587,2,FALSE),"") -> 114048 | CA11: =IFERROR(VLOOKUP(CA10,'Module Items'!$A$1:$B$2587,2,FALSE),"") -> 159056 | CB11: =IFERROR(VLOOKUP(CB10,'Module Items'!$A$1:$B$2587,2,FALSE),"") -> 118835 | CC11: =IFERROR(VLOOKUP(CC10,'Module Items'!$A$1:$B$2587,2,FALSE),"") -> 113391 | CD11: =IFERROR(VLOOKUP(CD10,'Module Items'!$A$1:$B$2587,2,FALSE),"") -> 142421 | CE11: =IFERROR(VLOOKUP(CE10,'Module Items'!$A$1:$B$2587,2,FALSE),"") -> 101017 | CF11: =IFERROR(VLOOKUP(CF10,'Module Items'!$A$1:$B$2587,2,FALSE),"") -> 49170 | ... DB11: =IFERROR(VLOOKUP(DB10,'Module Items'!$A$1:$B$2587,2,FALSE),"") -> 177644 | DC11: M13-1-1A08 | DD11: =IFERROR(VLOOKUP(DC11,'Module Items'!$A$1:$B$2587,2,FALSE),"") -> 120173 | DE11: =IFERROR(VLOOKUP(DC11,'Monthly Line Picks'!$A$1:$D$2000,4,FALSE),"0") -> 28 | DF11: M13-1-1B07 | DG11: =IFERROR(VLOOKUP(DF11,'Module Items'!$A$1:$B$2587,2,FALSE),"") -> 95684 | DH11: =IFERROR(VLOOKUP(DF11,'Monthly Line Picks'!$A$1:$D$2000,4,FALSE),"0") -> 5 | DI11: WALK-IN SHELVES | DL11: M13-1-1D10 | DM11: =IFERROR(VLOOKUP(DL11,'Module Items'!$A$1:$B$2587,2,FALSE),"") -> 1811 | DN11: =IFERROR(VLOOKUP(DL11,'Monthly Line Picks'!$A$1:$D$2000,4,FALSE),"0") -> 159 | DO11: M13-1-1E09 | DP11: =IFERROR(VLOOKUP(DO11,'Module Items'!$A$1:$B$2587,2,FALSE),"") -> 1428 | DQ11: =IFERROR(VLOOKUP(DO11,'Monthly Line Picks'!$A$1:$D$2000,4,FALSE),"0") -> 7 | DS11: =IFERROR(VLOOKUP(DR11,'Module Items'!$A$1:$B$2587,2,FALSE),"")
K12: =IFERROR(VLOOKUP(K10,'Monthly Line Picks'!$A$1:$D$2101,4,FALSE),"0") -> 6 | L12: =IFERROR(VLOOKUP(L10,'Monthly Line Picks'!$A$1:$D$2101,4,FALSE),"0") -> 12 | M12: =IFERROR(VLOOKUP(M10,'Monthly Line Picks'!$A$1:$D$2101,4,FALSE),"0") -> 40 | N12: =IFERROR(VLOOKUP(N10,'Monthly Line Picks'!$A$1:$D$2101,4,FALSE),"0") -> 3 | O12: =IFERROR(VLOOKUP(O10,'Monthly Line Picks'!$A$1:$D$2101,4,FALSE),"0") -> 21 | P12: =IFERROR(VLOOKUP(P10,'Monthly Line Picks'!$A$1:$D$2101,4,FALSE),"0") -> 5 | Q12: =IFERROR(VLOOKUP(Q10,'Monthly Line Picks'!$A$1:$D$2101,4,FALSE),"0") -> 56 | R12: =IFERROR(VLOOKUP(R10,'Monthly Line Picks'!$A$1:$D$2101,4,FALSE),"0") -> 6 | ... T12: =IFERROR(VLOOKUP(T10,'Monthly Line Picks'!$A$1:$D$2101,4,FALSE),"0") -> 12 | V12: =IFERROR(VLOOKUP(V10,'Monthly Line Picks'!$A$1:$D$2101,4,FALSE),"0") -> 14 | W12: =IFERROR(VLOOKUP(W10,'Monthly Line Picks'!$A$1:$D$2101,4,FALSE),"0") -> 231 | X12: =IFERROR(VLOOKUP(X10,'Monthly Line Picks'!$A$1:$D$2101,4,FALSE),"0") -> 0 | Y12: =IFERROR(VLOOKUP(Y10,'Monthly Line Picks'!$A$1:$D$2101,4,FALSE),"0") -> 4 | Z12: =IFERROR(VLOOKUP(Z10,'Monthly Line Picks'!$A$1:$D$2101,4,FALSE),"0") -> 14 | AA12: =IFERROR(VLOOKUP(AA10,'Monthly Line Picks'!$A$1:$D$2101,4,FALSE),"0") -> 0 | AB12: =IFERROR(VLOOKUP(AB10,'Monthly Line Picks'!$A$1:$D$2101,4,FALSE),"0") -> 7 | AC12: =IFERROR(VLOOKUP(AC10,'Monthly Line Picks'!$A$1:$D$2101,4,FALSE),"0") -> 8 | ... AZ12: =IFERROR(VLOOKUP(AZ10,'Monthly Line Picks'!$A$1:$D$2101,4,FALSE),"0") -> 27 | BA12: M13-1-8A09 | BB12: =IFERROR(VLOOKUP(BA12,'Module Items'!$A$1:$B$2587,2,FALSE),"") -> 109387 | BC12: =IFERROR(VLOOKUP(BA12,'Monthly Line Picks'!$A$1:$D$2000,4,FALSE),"0") -> 17 | BD12: M13-1-8B08 | BE12: =IFERROR(VLOOKUP(BD12,'Module Items'!$A$1:$B$2587,2,FALSE),"") -> 335 | BF12: =IFERROR(VLOOKUP(BD12,'Monthly Line Picks'!$A$1:$D$2000,4,FALSE),"0") -> 11 | BK12: =IFERROR(VLOOKUP(BJ12,'Module Items'!$A$1:$B$2587,2,FALSE),"") | BL12: =IFERROR(VLOOKUP(BJ12,'Monthly Line Picks'!$A$1:$D$2101,4,FALSE),"") | BM12: M13-1-8E01 | BN12: =IFERROR(VLOOKUP(BM12,'Module Items'!$A$1:$B$2587,2,FALSE),"") -> 160071 | BO12: =IFERROR(VLOOKUP(BM12,'Monthly Line Picks'!$A$1:$D$2000,4,FALSE),"0") -> 35 | BP12: M13-1-8E10 | BQ12: =IFERROR(VLOOKUP(BP12,'Module Items'!$A$1:$B$2587,2,FALSE),"") -> 82322 | BR12: =IFERROR(VLOOKUP(BP12,'Monthly Line Picks'!$A$1:$D$2000,4,FALSE),"0") -> 0 | BY12: =IFERROR(VLOOKUP(BY10,'Monthly Line Picks'!$A$1:$D$1458,4,FALSE),"0") -> 28 | BZ12: =IFERROR(VLOOKUP(BZ10,'Monthly Line Picks'!$A$1:$D$1458,4,FALSE),"0") -> 42 | CA12: =IFERROR(VLOOKUP(CA10,'Monthly Line Picks'!$A$1:$D$1458,4,FALSE),"0") -> 21 | CB12: =IFERROR(VLOOKUP(CB10,'Monthly Line Picks'!$A$1:$D$1458,4,FALSE),"0") -> 10 | CC12: =IFERROR(VLOOKUP(CC10,'Monthly Line Picks'!$A$1:$D$1458,4,FALSE),"0") -> 15 | CD12: =IFERROR(VLOOKUP(CD10,'Monthly Line Picks'!$A$1:$D$1458,4,FALSE),"0") -> 21 | CE12: =IFERROR(VLOOKUP(CE10,'Monthly Line Picks'!$A$1:$D$1458,4,FALSE),"0") -> 3 | CF12: =IFERROR(VLOOKUP(CF10,'Monthly Line Picks'!$A$1:$D$1458,4,FALSE),"0") -> 0 | ... DB12: =IFERROR(VLOOKUP(DB10,'Monthly Line Picks'!$A$1:$D$1458,4,FALSE),"0") -> 69 | DC12: M13-1-1A09 | DD12: =IFERROR(VLOOKUP(DC12,'Module Items'!$A$1:$B$2587,2,FALSE),"") -> 108911 | DE12: =IFERROR(VLOOKUP(DC12,'Monthly Line Picks'!$A$1:$D$2000,4,FALSE),"0") -> 83 | DF12: M13-1-1B08 | DG12: =IFERROR(VLOOKUP(DF12,'Module Items'!$A$1:$B$2587,2,FALSE),"") -> 18602 | DH12: =IFERROR(VLOOKUP(DF12,'Monthly Line Picks'!$A$1:$D$2000,4,FALSE),"0") -> 2 | DL12: M13-1-1E01 | DM12: =IFERROR(VLOOKUP(DL12,'Module Items'!$A$1:$B$2587,2,FALSE),"") -> 13164 | DN12: =IFERROR(VLOOKUP(DL12,'Monthly Line Picks'!$A$1:$D$2000,4,FALSE),"0") -> 0 | DO12: M13-1-1E10 | DP12: =IFERROR(VLOOKUP(DO12,'Module Items'!$A$1:$B$2587,2,FALSE),"") -> 28728 | DQ12: =IFERROR(VLOOKUP(DO12,'Monthly Line Picks'!$A$1:$D$2000,4,FALSE),"0") -> 9 | DS12: =IFERROR(VLOOKUP(DR12,'Module Items'!$A$1:$B$2587,2,FALSE),"")
K13: ZONE 1 | BY13: ZONE 3
K15: ZONE 2 | BS15: WALKWAY | BV15: ZONE 4
C16: TOTE FARM - 8' BAY | K16: =IFERROR(VLOOKUP(K18,'Monthly Line Picks'!$A$1:$D$1458,4,FALSE),"0") -> 9 | L16: =IFERROR(VLOOKUP(L18,'Monthly Line Picks'!$A$1:$D$1458,4,FALSE),"0") -> 15 | M16: =IFERROR(VLOOKUP(M18,'Monthly Line Picks'!$A$1:$D$1458,4,FALSE),"0") -> 15 | N16: =IFERROR(VLOOKUP(N18,'Monthly Line Picks'!$A$1:$D$1458,4,FALSE),"0") -> 6 | O16: =IFERROR(VLOOKUP(O18,'Monthly Line Picks'!$A$1:$D$1458,4,FALSE),"0") -> 0 | P16: =IFERROR(VLOOKUP(P18,'Monthly Line Picks'!$A$1:$D$1458,4,FALSE),"0") -> 15 | Q16: =IFERROR(VLOOKUP(Q18,'Monthly Line Picks'!$A$1:$D$1458,4,FALSE),"0") -> 4 | R16: =IFERROR(VLOOKUP(R18,'Monthly Line Picks'!$A$1:$D$1458,4,FALSE),"0") -> 9 | ... AZ16: =IFERROR(VLOOKUP(AZ18,'Monthly Line Picks'!$A$1:$D$1458,4,FALSE),"0") -> 6 | BA16: M14-1-8A01 | BB16: =IFERROR(VLOOKUP(BA16,'Module Items'!$A$1:$B$2587,2,FALSE),"") -> 18561 | BC16: =IFERROR(VLOOKUP(BA16,'Monthly Line Picks'!$A$1:$D$2000,4,FALSE),"0") -> 0 | BD16: M14-1-8A10 | BE16: =IFERROR(VLOOKUP(BD16,'Module Items'!$A$1:$B$2587,2,FALSE),"") -> 100034 | BF16: =IFERROR(VLOOKUP(BD16,'Monthly Line Picks'!$A$1:$D$2000,4,FALSE),"0") -> 0 | BG16: WALK-IN SHELVES | BK16: =IFERROR(VLOOKUP(BJ16,'Module Items'!$A$1:$B$2587,2,FALSE),"") | BL16: =IFERROR(VLOOKUP(BJ16,'Monthly Line Picks'!$A$1:$D$2101,4,FALSE),"") | BM16: M14-1-8D03 | BN16: =IFERROR(VLOOKUP(BM16,'Module Items'!$A$1:$B$2587,2,FALSE),"") -> 100055 | BO16: =IFERROR(VLOOKUP(BM16,'Monthly Line Picks'!$A$1:$D$2000,4,FALSE),"0") -> 0 | BP16: M14-1-8E02 | BQ16: =IFERROR(VLOOKUP(BP16,'Module Items'!$A$1:$B$2587,2,FALSE),"") -> 105593 | BR16: =IFERROR(VLOOKUP(BP16,'Monthly Line Picks'!$A$1:$D$2000,4,FALSE),"0") -> 0 | BV16: =IFERROR(VLOOKUP(BV18,'Monthly Line Picks'!$A$1:$D$1458,4,FALSE),"0") -> 13 | BW16: =IFERROR(VLOOKUP(BW18,'Monthly Line Picks'!$A$1:$D$1458,4,FALSE),"0") -> 9 | BX16: =IFERROR(VLOOKUP(BX18,'Monthly Line Picks'!$A$1:$D$1458,4,FALSE),"0") -> 17 | BY16: =IFERROR(VLOOKUP(BY18,'Monthly Line Picks'!$A$1:$D$1458,4,FALSE),"0") -> 0 | BZ16: =IFERROR(VLOOKUP(BZ18,'Monthly Line Picks'!$A$1:$D$1458,4,FALSE),"0") -> 0 | CA16: =IFERROR(VLOOKUP(CA18,'Monthly Line Picks'!$A$1:$D$1458,4,FALSE),"0") -> 0 | CB16: =IFERROR(VLOOKUP(CB18,'Monthly Line Picks'!$A$1:$D$1458,4,FALSE),"0") -> 0 | CC16: =IFERROR(VLOOKUP(CC18,'Monthly Line Picks'!$A$1:$D$1458,4,FALSE),"0") -> 563 | ... DB16: =IFERROR(VLOOKUP(DB18,'Monthly Line Picks'!$A$1:$D$1458,4,FALSE),"0") -> 27 | DC16: M14-1-1A01 | DD16: =IFERROR(VLOOKUP(DC16,'Module Items'!$A$1:$B$2587,2,FALSE),"") -> 1961 | DE16: =IFERROR(VLOOKUP(DC16,'Monthly Line Picks'!$A$1:$D$2000,4,FALSE),"0") -> 0 | DF16: M14-1-1A10 | DG16: =IFERROR(VLOOKUP(DF16,'Module Items'!$A$1:$B$2587,2,FALSE),"") -> 39949 | DH16: =IFERROR(VLOOKUP(DF16,'Monthly Line Picks'!$A$1:$D$2000,4,FALSE),"0") -> 0 | DI16: WALK-IN SHELVES | DO16: M14-1-1D03 | DP16: =IFERROR(VLOOKUP(DO16,'Module Items'!$A$1:$B$2587,2,FALSE),"") -> 88150 | DQ16: =IFERROR(VLOOKUP(DO16,'Monthly Line Picks'!$A$1:$D$2000,4,FALSE),"0") -> 17 | DR16: M14-1-1E02 | DS16: =IFERROR(VLOOKUP(DR16,'Module Items'!$A$1:$B$2587,2,FALSE),"") -> 23505 | DT16: =IFERROR(VLOOKUP(DR16,'Monthly Line Picks'!$A$1:$D$2000,4,FALSE),"0") -> 2
K17: =IFERROR(VLOOKUP(K18,'Module Items'!$A$1:$B$2587,2,FALSE),"") -> 77307 | L17: =IFERROR(VLOOKUP(L18,'Module Items'!$A$1:$B$2587,2,FALSE),"") -> 177436 | M17: =IFERROR(VLOOKUP(M18,'Module Items'!$A$1:$B$2587,2,FALSE),"") -> 35294 | N17: =IFERROR(VLOOKUP(N18,'Module Items'!$A$1:$B$2587,2,FALSE),"") -> 176167 | O17: =IFERROR(VLOOKUP(O18,'Module Items'!$A$1:$B$2587,2,FALSE),"") -> 1045 | P17: =IFERROR(VLOOKUP(P18,'Module Items'!$A$1:$B$2587,2,FALSE),"") -> 223313 | Q17: =IFERROR(VLOOKUP(Q18,'Module Items'!$A$1:$B$2587,2,FALSE),"") -> 155908 | R17: =IFERROR(VLOOKUP(R18,'Module Items'!$A$1:$B$2587,2,FALSE),"") -> 125447 | ... AZ17: =IFERROR(VLOOKUP(AZ18,'Module Items'!$A$1:$B$2587,2,FALSE),"") -> 131599 | BA17: M14-1-8A02 | BB17: =IFERROR(VLOOKUP(BA17,'Module Items'!$A$1:$B$2587,2,FALSE),"") -> 83415 | BC17: =IFERROR(VLOOKUP(BA17,'Monthly Line Picks'!$A$1:$D$2000,4,FALSE),"0") -> 1 | BD17: M14-1-8B01 | BE17: =IFERROR(VLOOKUP(BD17,'Module Items'!$A$1:$B$2587,2,FALSE),"") -> 105354 | BF17: =IFERROR(VLOOKUP(BD17,'Monthly Line Picks'!$A$1:$D$2000,4,FALSE),"0") -> 0 | BK17: =IFERROR(VLOOKUP(BJ17,'Module Items'!$A$1:$B$2587,2,FALSE),"") | BL17: =IFERROR(VLOOKUP(BJ17,'Monthly Line Picks'!$A$1:$D$2101,4,FALSE),"") | BM17: M14-1-8D04 | BN17: =IFERROR(VLOOKUP(BM17,'Module Items'!$A$1:$B$2587,2,FALSE),"") -> 101120 | BO17: =IFERROR(VLOOKUP(BM17,'Monthly Line Picks'!$A$1:$D$2000,4,FALSE),"0") -> 0 | BP17: M14-1-8E03 | BQ17: =IFERROR(VLOOKUP(BP17,'Module Items'!$A$1:$B$2587,2,FALSE),"") -> 4133 | BR17: =IFERROR(VLOOKUP(BP17,'Monthly Line Picks'!$A$1:$D$2000,4,FALSE),"0") -> 8 | BV17: =IFERROR(VLOOKUP(BV18,'Module Items'!$A$1:$B$2587,2,FALSE),"") -> 178520 | BW17: =IFERROR(VLOOKUP(BW18,'Module Items'!$A$1:$B$2587,2,FALSE),"") -> 130155 | BX17: =IFERROR(VLOOKUP(BX18,'Module Items'!$A$1:$B$2587,2,FALSE),"") -> 132826 | BY17: =IFERROR(VLOOKUP(BY18,'Module Items'!$A$1:$B$2587,2,FALSE),"") | BZ17: =IFERROR(VLOOKUP(BZ18,'Module Items'!$A$1:$B$2587,2,FALSE),"") | CA17: =IFERROR(VLOOKUP(CA18,'Module Items'!$A$1:$B$2587,2,FALSE),"") | CB17: =IFERROR(VLOOKUP(CB18,'Module Items'!$A$1:$B$2587,2,FALSE),"") | CC17: =IFERROR(VLOOKUP(CC18,'Module Items'!$A$1:$B$2587,2,FALSE),"") -> 111867 | ... DB17: =IFERROR(VLOOKUP(DB18,'Module Items'!$A$1:$B$2587,2,FALSE),"") -> 137870 | DC17: M14-1-1A02 | DD17: =IFERROR(VLOOKUP(DC17,'Module Items'!$A$1:$B$2587,2,FALSE),"") -> 849 | DE17: =IFERROR(VLOOKUP(DC17,'Monthly Line Picks'!$A$1:$D$2000,4,FALSE),"0") -> 1 | DF17: M14-1-1B01 | DG17: =IFERROR(VLOOKUP(DF17,'Module Items'!$A$1:$B$2587,2,FALSE),"") -> 112422 | DH17: =IFERROR(VLOOKUP(DF17,'Monthly Line Picks'!$A$1:$D$2000,4,FALSE),"0") -> 12 | DO17: M14-1-1D04 | DP17: =IFERROR(VLOOKUP(DO17,'Module Items'!$A$1:$B$2587,2,FALSE),"") -> 109336 | DQ17: =IFERROR(VLOOKUP(DO17,'Monthly Line Picks'!$A$1:$D$2000,4,FALSE),"0") -> 0 | DR17: M14-1-1E03 | DS17: =IFERROR(VLOOKUP(DR17,'Module Items'!$A$1:$B$2587,2,FALSE),"") -> 157507 | DT17: =IFERROR(VLOOKUP(DR17,'Monthly Line Picks'!$A$1:$D$2000,4,FALSE),"0") -> 24
K18: M12-1-6A06 | L18: M12-1-6A05 | M18: M12-1-6A04 | N18: M12-1-6A03 | O18: M12-1-6A02 | P18: M12-1-6A01 | Q18: M12-1-5A06 | R18: M12-1-5A05 | S18: M12-1-5A04 | T18: M12-1-5A03 | U18: M12-1-5A02 | V18: M12-1-5A01 | W18: M12-1-4A06 | X18: M12-1-4A05 | Y18: M12-1-4A04 | Z18: M12-1-4A03 | AA18: M12-1-4A02 | AB18: M12-1-4A01 | AC18: M12-1-3A06 | AD18: M12-1-3A05 | AE18: M12-1-3A04 | AF18: M12-1-3A03 | AG18: M12-1-3A02 | AH18: M12-1-3A01 | AI18: M12-1-2A06 | AJ18: M12-1-2A05 | AK18: M12-1-2A04 | AL18: M12-1-2A03 | AM18: M12-1-2A02 | AN18: M12-1-2A01 | AO18: M12-1-1A06 | AP18: M12-1-1A05 | AQ18: M12-1-1A04 | AR18: M12-1-1A03 | AS18: M12-1-1A02 | AT18: M12-1-1A01 | AU18: M14-1-9A06 | AV18: M14-1-9A05 | AW18: M14-1-9A04 | AX18: M14-1-9A03 | AY18: M14-1-9A02 | AZ18: M14-1-9A01 | BA18: M14-1-8A03 | BB18: =IFERROR(VLOOKUP(BA18,'Module Items'!$A$1:$B$2587,2,FALSE),"") | BC18: =IFERROR(VLOOKUP(BA18,'Monthly Line Picks'!$A$1:$D$2000,4,FALSE),"0") -> 0 | BD18: M14-1-8B02 | BE18: =IFERROR(VLOOKUP(BD18,'Module Items'!$A$1:$B$2587,2,FALSE),"") -> 61719 | BF18: =IFERROR(VLOOKUP(BD18,'Monthly Line Picks'!$A$1:$D$2000,4,FALSE),"0") -> 2 | BG18: M14-1-8B09 | BH18: =IFERROR(VLOOKUP(BG18,'Module Items'!$A$1:$B$2587,2,FALSE),"") -> 105207 | BI18: =IFERROR(VLOOKUP(BG18,'Monthly Line Picks'!$A$1:$D$2000,4,FALSE),"0") -> 0 | BJ18: M14-1-8C06 | BK18: =IFERROR(VLOOKUP(BJ18,'Module Items'!$A$1:$B$2587,2,FALSE),"") -> 109392 | BL18: =IFERROR(VLOOKUP(BJ18,'Monthly Line Picks'!$A$1:$D$2000,4,FALSE),"0") -> 3 | BM18: M14-1-8D05 | BN18: =IFERROR(VLOOKUP(BM18,'Module Items'!$A$1:$B$2587,2,FALSE),"") -> 101296 | BO18: =IFERROR(VLOOKUP(BM18,'Monthly Line Picks'!$A$1:$D$2000,4,FALSE),"0") -> 0 | BP18: M14-1-8E04 | BQ18: =IFERROR(VLOOKUP(BP18,'Module Items'!$A$1:$B$2587,2,FALSE),"") -> 101571 | BR18: =IFERROR(VLOOKUP(BP18,'Monthly Line Picks'!$A$1:$D$2000,4,FALSE),"0") -> 1 | BV18: M14-1-7A03 | BW18: M14-1-7A02 | BX18: M14-1-7A01 | BY18: M14-1-6A06 | BZ18: M14-1-6A05 | CA18: M14-1-6A04 | CB18: M14-1-6A03 | CC18: M14-1-6A02 | CD18: M14-1-6A01 | CE18: M14-1-5A06 | CF18: M14-1-5A05 | CG18: M14-1-5A04 | CH18: M14-1-5A03 | CI18: M14-1-5A02 | CJ18: M14-1-5A01 | CK18: M14-1-4A06 | CL18: M14-1-4A05 | CM18: M14-1-4A04 | CN18: M14-1-4A03 | CO18: M14-1-4A02 | CP18: M14-1-4A01 | CQ18: M14-1-3A06 | CR18: M14-1-3A05 | CS18: M14-1-3A04 | CT18: M14-1-3A03 | CU18: M14-1-3A02 | CV18: M14-1-3A01 | CW18: M14-1-2A06 | CX18: M14-1-2A05 | CY18: M14-1-2A04 | CZ18: M14-1-2A03 | DA18: M14-1-2A02 | DB18: M14-1-2A01 | DC18: M14-1-1A03 | DD18: =IFERROR(VLOOKUP(DC18,'Module Items'!$A$1:$B$2587,2,FALSE),"") -> 17407 | DE18: =IFERROR(VLOOKUP(DC18,'Monthly Line Picks'!$A$1:$D$2000,4,FALSE),"0") -> 1 | DF18: M14-1-1B02 | DG18: =IFERROR(VLOOKUP(DF18,'Module Items'!$A$1:$B$2587,2,FALSE),"") -> 174180 | DH18: =IFERROR(VLOOKUP(DF18,'Monthly Line Picks'!$A$1:$D$2000,4,FALSE),"0") -> 0 | DI18: M14-1-1B09 | DJ18: =IFERROR(VLOOKUP(DI18,'Module Items'!$A$1:$B$2587,2,FALSE),"") -> 158069 | DK18: =IFERROR(VLOOKUP(DI18,'Monthly Line Picks'!$A$1:$D$2000,4,FALSE),"0") -> 2 | DL18: M14-1-1C06 | DM18: =IFERROR(VLOOKUP(DL18,'Module Items'!$A$1:$B$2587,2,FALSE),"") -> 82462 | DN18: =IFERROR(VLOOKUP(DL18,'Monthly Line Picks'!$A$1:$D$2000,4,FALSE),"0") -> 5 | DO18: M14-1-1D05 | DP18: =IFERROR(VLOOKUP(DO18,'Module Items'!$A$1:$B$2587,2,FALSE),"") -> 177102 | DQ18: =IFERROR(VLOOKUP(DO18,'Monthly Line Picks'!$A$1:$D$2000,4,FALSE),"0") -> 0 | DR18: M14-1-1E04 | DS18: =IFERROR(VLOOKUP(DR18,'Module Items'!$A$1:$B$2587,2,FALSE),"") -> 365 | DT18: =IFERROR(VLOOKUP(DR18,'Monthly Line Picks'!$A$1:$D$2000,4,FALSE),"0") -> 9
K19: =IFERROR(VLOOKUP(K21,'Monthly Line Picks'!$A$1:$D$1458,4,FALSE),"0") -> 21 | L19: =IFERROR(VLOOKUP(L21,'Monthly Line Picks'!$A$1:$D$1458,4,FALSE),"0") -> 15 | M19: =IFERROR(VLOOKUP(M21,'Monthly Line Picks'!$A$1:$D$1458,4,FALSE),"0") -> 42 | N19: =IFERROR(VLOOKUP(N21,'Monthly Line Picks'!$A$1:$D$1458,4,FALSE),"0") -> 37 | O19: =IFERROR(VLOOKUP(O21,'Monthly Line Picks'!$A$1:$D$1458,4,FALSE),"0") -> 374 | P19: =IFERROR(VLOOKUP(P21,'Monthly Line Picks'!$A$1:$D$1458,4,FALSE),"0") -> 94 | Q19: =IFERROR(VLOOKUP(Q21,'Monthly Line Picks'!$A$1:$D$1458,4,FALSE),"0") -> 19 | R19: =IFERROR(VLOOKUP(R21,'Monthly Line Picks'!$A$1:$D$1458,4,FALSE),"0") -> 0 | ... AZ19: =IFERROR(VLOOKUP(AZ21,'Monthly Line Picks'!$A$1:$D$1458,4,FALSE),"0") -> 297 | BA19: M14-1-8A04 | BB19: =IFERROR(VLOOKUP(BA19,'Module Items'!$A$1:$B$2587,2,FALSE),"") -> 81887 | BC19: =IFERROR(VLOOKUP(BA19,'Monthly Line Picks'!$A$1:$D$2000,4,FALSE),"0") -> 0 | BD19: M14-1-8B03 | BE19: =IFERROR(VLOOKUP(BD19,'Module Items'!$A$1:$B$2587,2,FALSE),"") -> 100681 | BF19: =IFERROR(VLOOKUP(BD19,'Monthly Line Picks'!$A$1:$D$2000,4,FALSE),"0") -> 1 | BG19: M14-1-8B10 | BH19: =IFERROR(VLOOKUP(BG19,'Module Items'!$A$1:$B$2587,2,FALSE),"") -> 105901 | BI19: =IFERROR(VLOOKUP(BG19,'Monthly Line Picks'!$A$1:$D$2000,4,FALSE),"0") -> 1 | BJ19: M14-1-8C07 | BK19: =IFERROR(VLOOKUP(BJ19,'Module Items'!$A$1:$B$2587,2,FALSE),"") -> 3939 | BL19: =IFERROR(VLOOKUP(BJ19,'Monthly Line Picks'!$A$1:$D$2000,4,FALSE),"0") -> 0 | BM19: M14-1-8D06 | BN19: =IFERROR(VLOOKUP(BM19,'Module Items'!$A$1:$B$2587,2,FALSE),"") -> 105893 | BO19: =IFERROR(VLOOKUP(BM19,'Monthly Line Picks'!$A$1:$D$2000,4,FALSE),"0") -> 2 | BP19: M14-1-8E05 | BQ19: =IFERROR(VLOOKUP(BP19,'Module Items'!$A$1:$B$2587,2,FALSE),"") -> 82236 | BR19: =IFERROR(VLOOKUP(BP19,'Monthly Line Picks'!$A$1:$D$2000,4,FALSE),"0") -> 0 | BV19: =IFERROR(VLOOKUP(BV21,'Monthly Line Picks'!$A$1:$D$1458,4,FALSE),"0") -> 8 | BW19: =IFERROR(VLOOKUP(BW21,'Monthly Line Picks'!$A$1:$D$1458,4,FALSE),"0") -> 12 | BX19: =IFERROR(VLOOKUP(BX21,'Monthly Line Picks'!$A$1:$D$1458,4,FALSE),"0") -> 7 | BY19: =IFERROR(VLOOKUP(BY21,'Monthly Line Picks'!$A$1:$D$1458,4,FALSE),"0") -> 0 | BZ19: =IFERROR(VLOOKUP(BZ21,'Monthly Line Picks'!$A$1:$D$1458,4,FALSE),"0") -> 0 | CA19: =IFERROR(VLOOKUP(CA21,'Monthly Line Picks'!$A$1:$D$1458,4,FALSE),"0") -> 0 | CB19: =IFERROR(VLOOKUP(CB21,'Monthly Line Picks'!$A$1:$D$1458,4,FALSE),"0") -> 0 | CC19: =IFERROR(VLOOKUP(CC21,'Monthly Line Picks'!$A$1:$D$1458,4,FALSE),"0") -> 0 | ... DB19: =IFERROR(VLOOKUP(DB21,'Monthly Line Picks'!$A$1:$D$1458,4,FALSE),"0") -> 13 | DC19: M14-1-1A04 | DD19: =IFERROR(VLOOKUP(DC19,'Module Items'!$A$1:$B$2587,2,FALSE),"") -> 82494 | DE19: =IFERROR(VLOOKUP(DC19,'Monthly Line Picks'!$A$1:$D$2000,4,FALSE),"0") -> 4 | DF19: M14-1-1B03 | DG19: =IFERROR(VLOOKUP(DF19,'Module Items'!$A$1:$B$2587,2,FALSE),"") -> 158121 | DH19: =IFERROR(VLOOKUP(DF19,'Monthly Line Picks'!$A$1:$D$2000,4,FALSE),"0") -> 1 | DI19: M14-1-1B10 | DJ19: =IFERROR(VLOOKUP(DI19,'Module Items'!$A$1:$B$2587,2,FALSE),"") -> 157431 | DK19: =IFERROR(VLOOKUP(DI19,'Monthly Line Picks'!$A$1:$D$2000,4,FALSE),"0") -> 2 | DL19: M14-1-1C07 | DM19: =IFERROR(VLOOKUP(DL19,'Module Items'!$A$1:$B$2587,2,FALSE),"") -> 141049 | DN19: =IFERROR(VLOOKUP(DL19,'Monthly Line Picks'!$A$1:$D$2000,4,FALSE),"0") -> 5 | DO19: M14-1-1D06 | DP19: =IFERROR(VLOOKUP(DO19,'Module Items'!$A$1:$B$2587,2,FALSE),"") -> 134469 | DQ19: =IFERROR(VLOOKUP(DO19,'Monthly Line Picks'!$A$1:$D$2000,4,FALSE),"0") -> 0 | DR19: M14-1-1E05 | DS19: =IFERROR(VLOOKUP(DR19,'Module Items'!$A$1:$B$2587,2,FALSE),"") -> 72343 | DT19: =IFERROR(VLOOKUP(DR19,'Monthly Line Picks'!$A$1:$D$2000,4,FALSE),"0") -> 0
K20: =IFERROR(VLOOKUP(K21,'Module Items'!$A$1:$B$2587,2,FALSE),"") -> 141177 | L20: =IFERROR(VLOOKUP(L21,'Module Items'!$A$1:$B$2587,2,FALSE),"") -> 97690 | M20: =IFERROR(VLOOKUP(M21,'Module Items'!$A$1:$B$2587,2,FALSE),"") -> 172563 | N20: =IFERROR(VLOOKUP(N21,'Module Items'!$A$1:$B$2587,2,FALSE),"") -> 120005 | O20: =IFERROR(VLOOKUP(O21,'Module Items'!$A$1:$B$2587,2,FALSE),"") -> 100771 | P20: =IFERROR(VLOOKUP(P21,'Module Items'!$A$1:$B$2587,2,FALSE),"") -> 177009 | Q20: =IFERROR(VLOOKUP(Q21,'Module Items'!$A$1:$B$2587,2,FALSE),"") -> 18869 | R20: =IFERROR(VLOOKUP(R21,'Module Items'!$A$1:$B$2587,2,FALSE),"") -> 155913 | ... AZ20: =IFERROR(VLOOKUP(AZ21,'Module Items'!$A$1:$B$2587,2,FALSE),"") -> 178640 | BA20: M14-1-8A05 | BB20: =IFERROR(VLOOKUP(BA20,'Module Items'!$A$1:$B$2587,2,FALSE),"") -> 108160 | BC20: =IFERROR(VLOOKUP(BA20,'Monthly Line Picks'!$A$1:$D$2000,4,FALSE),"0") -> 0 | BD20: M14-1-8B04 | BE20: =IFERROR(VLOOKUP(BD20,'Module Items'!$A$1:$B$2587,2,FALSE),"") -> 58217 | BF20: =IFERROR(VLOOKUP(BD20,'Monthly Line Picks'!$A$1:$D$2000,4,FALSE),"0") -> 4 | BG20: M14-1-8C01 | BH20: =IFERROR(VLOOKUP(BG20,'Module Items'!$A$1:$B$2587,2,FALSE),"") -> 71465 | BI20: =IFERROR(VLOOKUP(BG20,'Monthly Line Picks'!$A$1:$D$2000,4,FALSE),"0") -> 0 | BJ20: M14-1-8C08 | BK20: =IFERROR(VLOOKUP(BJ20,'Module Items'!$A$1:$B$2587,2,FALSE),"") -> 65310 | BL20: =IFERROR(VLOOKUP(BJ20,'Monthly Line Picks'!$A$1:$D$2000,4,FALSE),"0") -> 0 | BM20: M14-1-8D07 | BN20: =IFERROR(VLOOKUP(BM20,'Module Items'!$A$1:$B$2587,2,FALSE),"") -> 66660 | BO20: =IFERROR(VLOOKUP(BM20,'Monthly Line Picks'!$A$1:$D$2000,4,FALSE),"0") -> 2 | BP20: M14-1-8E06 | BQ20: =IFERROR(VLOOKUP(BP20,'Module Items'!$A$1:$B$2587,2,FALSE),"") -> 132333 | BR20: =IFERROR(VLOOKUP(BP20,'Monthly Line Picks'!$A$1:$D$2000,4,FALSE),"0") -> 0 | BV20: =IFERROR(VLOOKUP(BV21,'Module Items'!$A$1:$B$2587,2,FALSE),"") -> 127300 | BW20: =IFERROR(VLOOKUP(BW21,'Module Items'!$A$1:$B$2587,2,FALSE),"") -> 18557 | BX20: =IFERROR(VLOOKUP(BX21,'Module Items'!$A$1:$B$2587,2,FALSE),"") -> 37456 | BY20: =IFERROR(VLOOKUP(BY21,'Module Items'!$A$1:$B$2587,2,FALSE),"") | BZ20: =IFERROR(VLOOKUP(BZ21,'Module Items'!$A$1:$B$2587,2,FALSE),"") | CA20: =IFERROR(VLOOKUP(CA21,'Module Items'!$A$1:$B$2587,2,FALSE),"") | CB20: =IFERROR(VLOOKUP(CB21,'Module Items'!$A$1:$B$2587,2,FALSE),"") | CC20: =IFERROR(VLOOKUP(CC21,'Module Items'!$A$1:$B$2587,2,FALSE),"") | ... DB20: =IFERROR(VLOOKUP(DB21,'Module Items'!$A$1:$B$2587,2,FALSE),"") -> 33299 | DC20: M14-1-1A05 | DD20: =IFERROR(VLOOKUP(DC20,'Module Items'!$A$1:$B$2587,2,FALSE),"") -> 37892 | DE20: =IFERROR(VLOOKUP(DC20,'Monthly Line Picks'!$A$1:$D$2000,4,FALSE),"0") -> 1 | DF20: M14-1-1B04 | DG20: =IFERROR(VLOOKUP(DF20,'Module Items'!$A$1:$B$2587,2,FALSE),"") -> 18058 | DH20: =IFERROR(VLOOKUP(DF20,'Monthly Line Picks'!$A$1:$D$2000,4,FALSE),"0") -> 3 | DI20: M14-1-1C01 | DJ20: =IFERROR(VLOOKUP(DI20,'Module Items'!$A$1:$B$2587,2,FALSE),"") -> 59361 | DK20: =IFERROR(VLOOKUP(DI20,'Monthly Line Picks'!$A$1:$D$2000,4,FALSE),"0") -> 4 | DL20: M14-1-1C08 | DM20: =IFERROR(VLOOKUP(DL20,'Module Items'!$A$1:$B$2587,2,FALSE),"") -> 306 | DN20: =IFERROR(VLOOKUP(DL20,'Monthly Line Picks'!$A$1:$D$2000,4,FALSE),"0") -> 13 | DO20: M14-1-1D07 | DP20: =IFERROR(VLOOKUP(DO20,'Module Items'!$A$1:$B$2587,2,FALSE),"") -> 137308 | DQ20: =IFERROR(VLOOKUP(DO20,'Monthly Line Picks'!$A$1:$D$2000,4,FALSE),"0") -> 3 | DR20: M14-1-1E06 | DS20: =IFERROR(VLOOKUP(DR20,'Module Items'!$A$1:$B$2587,2,FALSE),"") -> 176177 | DT20: =IFERROR(VLOOKUP(DR20,'Monthly Line Picks'!$A$1:$D$2000,4,FALSE),"0") -> 0
K21: M12-1-6B06 | L21: M12-1-6B05 | M21: M12-1-6B04 | N21: M12-1-6B03 | O21: M12-1-6B02 | P21: M12-1-6B01 | Q21: M12-1-5B06 | R21: M12-1-5B05 | S21: M12-1-5B04 | T21: M12-1-5B03 | U21: M12-1-5B02 | V21: M12-1-5B01 | W21: M12-1-4B06 | X21: M12-1-4B05 | Y21: M12-1-4B04 | Z21: M12-1-4B03 | AA21: M12-1-4B02 | AB21: M12-1-4B01 | AC21: M12-1-3B06 | AD21: M12-1-3B05 | AE21: M12-1-3B04 | AF21: M12-1-3B03 | AG21: M12-1-3B02 | AH21: M12-1-3B01 | AI21: M12-1-2B06 | AJ21: M12-1-2B05 | AK21: M12-1-2B04 | AL21: M12-1-2B03 | AM21: M12-1-2B02 | AN21: M12-1-2B01 | AO21: M12-1-1B06 | AP21: M12-1-1B05 | AQ21: M12-1-1B04 | AR21: M12-1-1B03 | AS21: M12-1-1B02 | AT21: M12-1-1B01 | AU21: M14-1-9B06 | AV21: M14-1-9B05 | AW21: M14-1-9B04 | AX21: M14-1-9B03 | AY21: M14-1-9B02 | AZ21: M14-1-9B01 | BA21: M14-1-8A06 | BB21: =IFERROR(VLOOKUP(BA21,'Module Items'!$A$1:$B$2587,2,FALSE),"") -> 125972 | BC21: =IFERROR(VLOOKUP(BA21,'Monthly Line Picks'!$A$1:$D$2000,4,FALSE),"0") -> 0 | BD21: M14-1-8B05 | BE21: =IFERROR(VLOOKUP(BD21,'Module Items'!$A$1:$B$2587,2,FALSE),"") -> 60520 | BF21: =IFERROR(VLOOKUP(BD21,'Monthly Line Picks'!$A$1:$D$2000,4,FALSE),"0") -> 0 | BG21: M14-1-8C02 | BH21: =IFERROR(VLOOKUP(BG21,'Module Items'!$A$1:$B$2587,2,FALSE),"") -> 105892 | BI21: =IFERROR(VLOOKUP(BG21,'Monthly Line Picks'!$A$1:$D$2000,4,FALSE),"0") -> 0 | BJ21: M14-1-8C09 | BK21: =IFERROR(VLOOKUP(BJ21,'Module Items'!$A$1:$B$2587,2,FALSE),"") -> 41936 | BL21: =IFERROR(VLOOKUP(BJ21,'Monthly Line Picks'!$A$1:$D$2000,4,FALSE),"0") -> 0 | BM21: M14-1-8D08 | BN21: =IFERROR(VLOOKUP(BM21,'Module Items'!$A$1:$B$2587,2,FALSE),"") -> 125713 | BO21: =IFERROR(VLOOKUP(BM21,'Monthly Line Picks'!$A$1:$D$2000,4,FALSE),"0") -> 0 | BP21: M14-1-8E07 | BQ21: =IFERROR(VLOOKUP(BP21,'Module Items'!$A$1:$B$2587,2,FALSE),"") -> 60589 | BR21: =IFERROR(VLOOKUP(BP21,'Monthly Line Picks'!$A$1:$D$2000,4,FALSE),"0") -> 4 | BV21: M14-1-7B03 | BW21: M14-1-7B02 | BX21: M14-1-7B01 | BY21: M14-1-6B06 | BZ21: M14-1-6B05 | CA21: M14-1-6B04 | CB21: M14-1-6B03 | CC21: M14-1-6B02 | CD21: M14-1-6B01 | CE21: M14-1-5B06 | CF21: M14-1-5B05 | CG21: M14-1-5B04 | CH21: M14-1-5B03 | CI21: M14-1-5B02 | CJ21: M14-1-5B01 | CK21: M14-1-4B06 | CL21: M14-1-4B05 | CM21: M14-1-4B04 | CN21: M14-1-4B03 | CO21: M14-1-4B02 | CP21: M14-1-4B01 | CQ21: M14-1-3B06 | CR21: M14-1-3B05 | CS21: M14-1-3B04 | CT21: M14-1-3B03 | CU21: M14-1-3B02 | CV21: M14-1-3B01 | CW21: M14-1-2B06 | CX21: M14-1-2B05 | CY21: M14-1-2B04 | CZ21: M14-1-2B03 | DA21: M14-1-2B02 | DB21: M14-1-2B01 | DC21: M14-1-1A06 | DD21: =IFERROR(VLOOKUP(DC21,'Module Items'!$A$1:$B$2587,2,FALSE),"") -> 77663 | DE21: =IFERROR(VLOOKUP(DC21,'Monthly Line Picks'!$A$1:$D$2000,4,FALSE),"0") -> 1 | DF21: M14-1-1B05 | DG21: =IFERROR(VLOOKUP(DF21,'Module Items'!$A$1:$B$2587,2,FALSE),"") -> 158001 | DH21: =IFERROR(VLOOKUP(DF21,'Monthly Line Picks'!$A$1:$D$2000,4,FALSE),"0") -> 5 | DI21: M14-1-1C02 | DJ21: =IFERROR(VLOOKUP(DI21,'Module Items'!$A$1:$B$2587,2,FALSE),"") -> 11491 | DK21: =IFERROR(VLOOKUP(DI21,'Monthly Line Picks'!$A$1:$D$2000,4,FALSE),"0") -> 3 | DL21: M14-1-1C09 | DM21: =IFERROR(VLOOKUP(DL21,'Module Items'!$A$1:$B$2587,2,FALSE),"") -> 1078 | DN21: =IFERROR(VLOOKUP(DL21,'Monthly Line Picks'!$A$1:$D$2000,4,FALSE),"0") -> 2 | DO21: M14-1-1D08 | DP21: =IFERROR(VLOOKUP(DO21,'Module Items'!$A$1:$B$2587,2,FALSE),"") -> 17408 | DQ21: =IFERROR(VLOOKUP(DO21,'Monthly Line Picks'!$A$1:$D$2000,4,FALSE),"0") -> 12 | DR21: M14-1-1E07 | DS21: =IFERROR(VLOOKUP(DR21,'Module Items'!$A$1:$B$2587,2,FALSE),"") -> 223208 | DT21: =IFERROR(VLOOKUP(DR21,'Monthly Line Picks'!$A$1:$D$2000,4,FALSE),"0") -> 4
K22: =IFERROR(VLOOKUP(K24,'Monthly Line Picks'!$A$1:$D$1458,4,FALSE),"0") -> 11 | L22: =IFERROR(VLOOKUP(L24,'Monthly Line Picks'!$A$1:$D$1458,4,FALSE),"0") -> 23 | M22: =IFERROR(VLOOKUP(M24,'Monthly Line Picks'!$A$1:$D$1458,4,FALSE),"0") -> 46 | N22: =IFERROR(VLOOKUP(N24,'Monthly Line Picks'!$A$1:$D$1458,4,FALSE),"0") -> 7 | O22: =IFERROR(VLOOKUP(O24,'Monthly Line Picks'!$A$1:$D$1458,4,FALSE),"0") -> 53 | P22: =IFERROR(VLOOKUP(P24,'Monthly Line Picks'!$A$1:$D$1458,4,FALSE),"0") -> 8 | Q22: =IFERROR(VLOOKUP(Q24,'Monthly Line Picks'!$A$1:$D$1458,4,FALSE),"0") -> 0 | R22: =IFERROR(VLOOKUP(R24,'Monthly Line Picks'!$A$1:$D$1458,4,FALSE),"0") -> 94 | ... AZ22: =IFERROR(VLOOKUP(AZ24,'Monthly Line Picks'!$A$1:$D$1458,4,FALSE),"0") -> 13 | BA22: M14-1-8A07 | BB22: =IFERROR(VLOOKUP(BA22,'Module Items'!$A$1:$B$2587,2,FALSE),"") -> 66944 | BC22: =IFERROR(VLOOKUP(BA22,'Monthly Line Picks'!$A$1:$D$2000,4,FALSE),"0") -> 0 | BD22: M14-1-8B06 | BE22: =IFERROR(VLOOKUP(BD22,'Module Items'!$A$1:$B$2587,2,FALSE),"") -> 127351 | BF22: =IFERROR(VLOOKUP(BD22,'Monthly Line Picks'!$A$1:$D$2000,4,FALSE),"0") -> 0 | BG22: M14-1-8C03 | BH22: =IFERROR(VLOOKUP(BG22,'Module Items'!$A$1:$B$2587,2,FALSE),"") -> 133655 | BI22: =IFERROR(VLOOKUP(BG22,'Monthly Line Picks'!$A$1:$D$2000,4,FALSE),"0") -> 0 | BJ22: M14-1-8C10 | BK22: =IFERROR(VLOOKUP(BJ22,'Module Items'!$A$1:$B$2587,2,FALSE),"") -> 101359 | BL22: =IFERROR(VLOOKUP(BJ22,'Monthly Line Picks'!$A$1:$D$2000,4,FALSE),"0") -> 3 | BM22: M14-1-8D09 | BN22: =IFERROR(VLOOKUP(BM22,'Module Items'!$A$1:$B$2587,2,FALSE),"") -> 77717 | BO22: =IFERROR(VLOOKUP(BM22,'Monthly Line Picks'!$A$1:$D$2000,4,FALSE),"0") -> 0 | BP22: M14-1-8E08 | BQ22: =IFERROR(VLOOKUP(BP22,'Module Items'!$A$1:$B$2587,2,FALSE),"") -> 71432 | BR22: =IFERROR(VLOOKUP(BP22,'Monthly Line Picks'!$A$1:$D$2000,4,FALSE),"0") -> 1 | BV22: =IFERROR(VLOOKUP(BV24,'Monthly Line Picks'!$A$1:$D$1458,4,FALSE),"0") -> 18 | BW22: =IFERROR(VLOOKUP(BW24,'Monthly Line Picks'!$A$1:$D$1458,4,FALSE),"0") -> 4 | BX22: =IFERROR(VLOOKUP(BX24,'Monthly Line Picks'!$A$1:$D$1458,4,FALSE),"0") -> 6 | BY22: =IFERROR(VLOOKUP(BY24,'Monthly Line Picks'!$A$1:$D$1458,4,FALSE),"0") -> 0 | BZ22: =IFERROR(VLOOKUP(BZ24,'Monthly Line Picks'!$A$1:$D$1458,4,FALSE),"0") -> 0 | CA22: =IFERROR(VLOOKUP(CA24,'Monthly Line Picks'!$A$1:$D$1458,4,FALSE),"0") -> 0 | CB22: =IFERROR(VLOOKUP(CB24,'Monthly Line Picks'!$A$1:$D$1458,4,FALSE),"0") -> 0 | CC22: =IFERROR(VLOOKUP(CC24,'Monthly Line Picks'!$A$1:$D$1458,4,FALSE),"0") -> 0 | ... DB22: =IFERROR(VLOOKUP(DB24,'Monthly Line Picks'!$A$1:$D$1458,4,FALSE),"0") -> 12 | DC22: M14-1-1A07 | DD22: =IFERROR(VLOOKUP(DC22,'Module Items'!$A$1:$B$2587,2,FALSE),"") -> 11797 | DE22: =IFERROR(VLOOKUP(DC22,'Monthly Line Picks'!$A$1:$D$2000,4,FALSE),"0") -> 0 | DF22: M14-1-1B06 | DG22: =IFERROR(VLOOKUP(DF22,'Module Items'!$A$1:$B$2587,2,FALSE),"") -> 18396 | DH22: =IFERROR(VLOOKUP(DF22,'Monthly Line Picks'!$A$1:$D$2000,4,FALSE),"0") -> 18 | DI22: M14-1-1C03 | DJ22: =IFERROR(VLOOKUP(DI22,'Module Items'!$A$1:$B$2587,2,FALSE),"") -> 96259 | DK22: =IFERROR(VLOOKUP(DI22,'Monthly Line Picks'!$A$1:$D$2000,4,FALSE),"0") -> 9 | DL22: M14-1-1C10 | DM22: =IFERROR(VLOOKUP(DL22,'Module Items'!$A$1:$B$2587,2,FALSE),"") -> 10881 | DN22: =IFERROR(VLOOKUP(DL22,'Monthly Line Picks'!$A$1:$D$2000,4,FALSE),"0") -> 4 | DO22: M14-1-1D09 | DP22: =IFERROR(VLOOKUP(DO22,'Module Items'!$A$1:$B$2587,2,FALSE),"") -> 131519 | DQ22: =IFERROR(VLOOKUP(DO22,'Monthly Line Picks'!$A$1:$D$2000,4,FALSE),"0") -> 0 | DR22: M14-1-1E08 | DS22: =IFERROR(VLOOKUP(DR22,'Module Items'!$A$1:$B$2587,2,FALSE),"") -> 134069 | DT22: =IFERROR(VLOOKUP(DR22,'Monthly Line Picks'!$A$1:$D$2000,4,FALSE),"0") -> 8
